Workbook

Sheet GPUs
A1: GPU Specification Weights per Task | G1: CUDA Ready | H1: FP16 | I1: FP32 | J1: FP64 | K1: Base Clock | L1: Turbo Clock | M1: Pixel Fill Rate | N1: Texture Units | O1: RT Cores | Q1: Memory Capacity | R1: Memory Bus Width | S1: Memory Speed | T1: Power | AC1: Task
A2: Gaming | H2: 0 | I2: 0.05 | J2: 0 | K2: 0.15 | L2: 0.25 | M2: 0.1 | N2: 0.1 | O2: 0.1 | Q2: 0.1 | R2: 0.1 | S2: 0.1 | T2: 0.05 | AC2: Gaming | AD2: ML/AI | AE2: HPC | AF2: 3D Rendering
A3: ML/AI | H3: 0.3 | I3: 0.2 | J3: 0.05 | K3: 0.05 | L3: 0.05 | M3: 0 | N3: 0 | O3: 0 | Q3: 0.2 | R3: 0.1 | S3: 0.05 | T3: 0.05 | AC3: 3 | AD3: 10 | AE3: 2 | AF3: 3
A4: HPC | H4: 0 | I4: 0.15 | J4: 0.35 | K4: 0.05 | L4: 0 | M4: 0 | N4: 0 | O4: 0 | Q4: 0.15 | R4: 0.15 | S4: 0.1 | T4: 0
A5: 3D Rendering | H5: 0.05 | I5: 0.2 | J5: 0 | K5: 0.1 | L5: 0.1 | M5: 0.05 | N5: 0.05 | O5: 0.1 | Q5: 0.1 | R5: 0.1 | S5: 0.1 | T5: 0.05
A7: Scaling Factor | H7: 0.85 | I7: 0.9 | J7: 0.8 | K7: 0.9 | L7: 0.9 | M7: 0.85 | N7: 0.85 | O7: 0.8 | Q7: 0.65 | R7: 0.75 | S7: 0.8 | T7: -0.5
A8: GPU | B8: Code | C8: Brand | D8: Manufacturer | E8: Series | F8: Model | G8: CUDA Ready | H8: FP16 | I8: FP32 | J8: FP64 | K8: Base Clock | L8: Turbo Clock | M8: Pixel Fill Rate | N8: Texture Units | O8: RT Cores | P8: VRAM Type | Q8: Memory Capacity | R8: Memory Bus Width | S8: Memory Speed | T8: Power | U8: Power Connection | V8: PCIe Version | W8: Physical Lanes | X8: Wired Lanes | Y8: Price Min | Z8: Price Max | AA8: Link | AB8: Product | AC8: Gaming Score | AD8: ML/AI Score | AE8: HPC Score | AF8: 3D Rendering Score | AG8: Task Score
A9: NVIDIA GeForce RTX 3050 6GB | C9: NVIDIA | E9: RTX 3000 | F9: 3050 6GB | G9: 1 | H9: =AVERAGEIF('GPUs Products'!F$9:F$616,GPUs!F9,'GPUs Products'!H$9:H$616) -> 6.86 | I9: =AVERAGEIF('GPUs Products'!F$9:F$616,GPUs!F9,'GPUs Products'!I$9:I$616) -> 6.86 | J9: =AVERAGEIF('GPUs Products'!F$9:F$616,GPUs!F9,'GPUs Products'!J$9:J$616) -> 0.11 | K9: =AVERAGEIF('GPUs Products'!F$9:F$616,GPUs!F9,'GPUs Products'!K$9:K$616) -> 1750 | L9: =AVERAGEIF('GPUs Products'!F$9:F$616,GPUs!F9,'GPUs Products'!L$9:L$616) -> 1750 | M9: =AVERAGEIF('GPUs Products'!F$9:F$616,GPUs!F9,'GPUs Products'!M$9:M$616) -> 33.34 | N9: =AVERAGEIF('GPUs Products'!F$9:F$616,GPUs!F9,'GPUs Products'!N$9:N$616) -> 75.02 | O9: =AVERAGEIF('GPUs Products'!F$9:F$616,GPUs!F9,'GPUs Products'!O$9:O$616) -> 20 | P9: GDDR6 | Q9: =AVERAGEIF('GPUs Products'!F$9:F$616,GPUs!F9,'GPUs Products'!Q$9:Q$616) -> 6 | R9: =AVERAGEIF('GPUs Products'!F$9:F$616,GPUs!F9,'GPUs Products'!R$9:R$616) -> 96 | S9: =AVERAGEIF('GPUs Products'!F$9:F$616,GPUs!F9,'GPUs Products'!S$9:S$616) -> 14 | T9: =AVERAGEIF('GPUs Products'!F$9:F$616,GPUs!F9,'GPUs Products'!T$9:T$616) -> 70 | U9: - | V9: 4 | W9: 16 | X9: 8 | Y9: =AVERAGEIF('GPUs Products'!F$9:F$616,GPUs!F9,'GPUs Products'!Y$9:Y$616) -> 203.80333 | Z9: =AVERAGEIF('GPUs Products'!F$9:F$616,GPUs!F9,'GPUs Products'!Y$9:Y$616) -> 203.80333 | AC9: 1 | AD9: 1 | AE9: 1 | AF9: 1 | AG9: {=SUMPRODUCT(AC9:AF9 * AC$3:AF$3) / SUM(AC$3:AF$3)} -> 1
A10: NVIDIA GeForce RTX 3050 8GB | C10: NVIDIA | E10: RTX 3000 | F10: 3050 8GB | G10: 1 | H10: =AVERAGEIF('GPUs Products'!F$9:F$616,GPUs!F10,'GPUs Products'!H$9:H$616) -> 9.2251724 | I10: =AVERAGEIF('GPUs Products'!F$9:F$616,GPUs!F10,'GPUs Products'!I$9:I$616) -> 9.2251724 | J10: =AVERAGEIF('GPUs Products'!F$9:F$616,GPUs!F10,'GPUs Products'!J$9:J$616) -> 0.14241379 | K10: =AVERAGEIF('GPUs Products'!F$9:F$616,GPUs!F10,'GPUs Products'!K$9:K$616) -> 1750 | L10: =AVERAGEIF('GPUs Products'!F$9:F$616,GPUs!F10,'GPUs Products'!L$9:L$616) -> 1801.6207 | M10: =AVERAGEIF('GPUs Products'!F$9:F$616,GPUs!F10,'GPUs Products'!M$9:M$616) -> 49.46 | N10: =AVERAGEIF('GPUs Products'!F$9:F$616,GPUs!F10,'GPUs Products'!N$9:N$616) -> 124.2 | O10: =AVERAGEIF('GPUs Products'!F$9:F$616,GPUs!F10,'GPUs Products'!O$9:O$616) -> 30 | P10: GDDR6 | Q10: =AVERAGEIF('GPUs Products'!F$9:F$616,GPUs!F10,'GPUs Products'!Q$9:Q$616) -> 8 | R10: =AVERAGEIF('GPUs Products'!F$9:F$616,GPUs!F10,'GPUs Products'!R$9:R$616) -> 128 | S10: =AVERAGEIF('GPUs Products'!F$9:F$616,GPUs!F10,'GPUs Products'!S$9:S$616) -> 14 | T10: =AVERAGEIF('GPUs Products'!F$9:F$616,GPUs!F10,'GPUs Products'!T$9:T$616) -> 128.44828 | U10: 1x 6-Pin PCIe | V10: 4 | W10: 16 | X10: 8 | Y10: =AVERAGEIF('GPUs Products'!F$9:F$616,GPUs!F10,'GPUs Products'!Y$9:Y$616) -> 292.99103 | Z10: =AVERAGEIF('GPUs Products'!F$9:F$616,GPUs!F10,'GPUs Products'!Y$9:Y$616) -> 292.99103 | AC10: {=(SUMPRODUCT((H10:O10/H$9:O$9)^H$7:O$7*H$2:O$2)+SUMPRODUCT((Q10:T10/Q$9:T$9)^Q$7:T$7*Q$2:T$2))*(0.8^(1-G10))*AC$9} -> 1.2850996 | AD10: {=(SUMPRODUCT((H10:O10/H$9:O$9)^H$7:O$7*H$3:O$3)+SUMPRODUCT((Q10:T10/Q$9:T$9)^Q$7:T$7*Q$3:T$3))*(0.1^(1-G10))*AD$9} -> 1.2619202 | AE10: {=(SUMPRODUCT((H10:O10/H$9:O$9)^H$7:O$7*H$4:O$4)+SUMPRODUCT((Q10:T10/Q$9:T$9)^Q$7:T$7*Q$4:T$4))*AE$9} -> 1.1431166 | AF10: {=(SUMPRODUCT((H10:O10/H$9:O$9)^H$7:O$7*H$5:O$5)+SUMPRODUCT((Q10:T10/Q$9:T$9)^Q$7:T$7*Q$5:T$5))*AF$9} -> 1.1946054 | AG10: {=SUMPRODUCT(AC10:AF10 * AC$3:AF$3) / SUM(AC$3:AF$3)} -> 1.2413639
A11: NVIDIA GeForce RTX 3060 8GB | C11: NVIDIA | E11: RTX 3000 | F11: 3060 8GB | G11: 1 | H11: =AVERAGEIF('GPUs Products'!F$9:F$616,GPUs!F11,'GPUs Products'!H$9:H$616) -> 12.961818 | I11: =AVERAGEIF('GPUs Products'!F$9:F$616,GPUs!F11,'GPUs Products'!I$9:I$616) -> 12.961818 | J11: =AVERAGEIF('GPUs Products'!F$9:F$616,GPUs!F11,'GPUs Products'!J$9:J$616) -> 0.20181818 | K11: =AVERAGEIF('GPUs Products'!F$9:F$616,GPUs!F11,'GPUs Products'!K$9:K$616) -> 1875 | L11: =AVERAGEIF('GPUs Products'!F$9:F$616,GPUs!F11,'GPUs Products'!L$9:L$616) -> 1808.3636 | M11: =AVERAGEIF('GPUs Products'!F$9:F$616,GPUs!F11,'GPUs Products'!M$9:M$616) -> 63.36 | N11: =AVERAGEIF('GPUs Products'!F$9:F$616,GPUs!F11,'GPUs Products'!N$9:N$616) -> 85.29 | O11: =AVERAGEIF('GPUs Products'!F$9:F$616,GPUs!F11,'GPUs Products'!O$9:O$616) -> 28 | P11: GDDR6 | Q11: =AVERAGEIF('GPUs Products'!F$9:F$616,GPUs!F11,'GPUs Products'!Q$9:Q$616) -> 8 | R11: =AVERAGEIF('GPUs Products'!F$9:F$616,GPUs!F11,'GPUs Products'!R$9:R$616) -> 128 | S11: =AVERAGEIF('GPUs Products'!F$9:F$616,GPUs!F11,'GPUs Products'!S$9:S$616) -> 15 | T11: =AVERAGEIF('GPUs Products'!F$9:F$616,GPUs!F11,'GPUs Products'!T$9:T$616) -> 170 | U11: 1x 8-Pin PCIe | V11: 4 | W11: 16 | X11: 16 | Y11: =AVERAGEIF('GPUs Products'!F$9:F$616,GPUs!F11,'GPUs Products'!Y$9:Y$616) -> 413.69 | Z11: =AVERAGEIF('GPUs Products'!F$9:F$616,GPUs!F11,'GPUs Products'!Y$9:Y$616) -> 413.69 | AC11: {=(SUMPRODUCT((H11:O11/H$9:O$9)^H$7:O$7*H$2:O$2)+SUMPRODUCT((Q11:T11/Q$9:T$9)^Q$7:T$7*Q$2:T$2))*(0.8^(1-G11))*AC$9} -> 1.3031562 | AD11: {=(SUMPRODUCT((H11:O11/H$9:O$9)^H$7:O$7*H$3:O$3)+SUMPRODUCT((Q11:T11/Q$9:T$9)^Q$7:T$7*Q$3:T$3))*(0.1^(1-G11))*AD$9} -> 1.5059195 | AE11: {=(SUMPRODUCT((H11:O11/H$9:O$9)^H$7:O$7*H$4:O$4)+SUMPRODUCT((Q11:T11/Q$9:T$9)^Q$7:T$7*Q$4:T$4))*AE$9} -> 1.3605418 | AF11: {=(SUMPRODUCT((H11:O11/H$9:O$9)^H$7:O$7*H$5:O$5)+SUMPRODUCT((Q11:T11/Q$9:T$9)^Q$7:T$7*Q$5:T$5))*AF$9} -> 1.3052237 | AG11: {=SUMPRODUCT(AC11:AF11 * AC$3:AF$3) / SUM(AC$3:AF$3)} -> 1.4225232
A12: NVIDIA GeForce RTX 3060 12GB | C12: NVIDIA | E12: RTX 3000 | F12: 3060 12GB | G12: 1 | H12: =AVERAGEIF('GPUs Products'!F$9:F$616,GPUs!F12,'GPUs Products'!H$9:H$616) -> 13.056087 | I12: =AVERAGEIF('GPUs Products'!F$9:F$616,GPUs!F12,'GPUs Products'!I$9:I$616) -> 13.056087 | J12: =AVERAGEIF('GPUs Products'!F$9:F$616,GPUs!F12,'GPUs Products'!J$9:J$616) -> 0.20391304 | K12: =AVERAGEIF('GPUs Products'!F$9:F$616,GPUs!F12,'GPUs Products'!K$9:K$616) -> 1875 | L12: =AVERAGEIF('GPUs Products'!F$9:F$616,GPUs!F12,'GPUs Products'!L$9:L$616) -> 1821.3478 | M12: =AVERAGEIF('GPUs Products'!F$9:F$616,GPUs!F12,'GPUs Products'!M$9:M$616) -> 63.36 | N12: =AVERAGEIF('GPUs Products'!F$9:F$616,GPUs!F12,'GPUs Products'!N$9:N$616) -> 85.29 | O12: =AVERAGEIF('GPUs Products'!F$9:F$616,GPUs!F12,'GPUs Products'!O$9:O$616) -> 28 | P12: GDDR6 | Q12: =AVERAGEIF('GPUs Products'!F$9:F$616,GPUs!F12,'GPUs Products'!Q$9:Q$616) -> 12 | R12: =AVERAGEIF('GPUs Products'!F$9:F$616,GPUs!F12,'GPUs Products'!R$9:R$616) -> 192 | S12: =AVERAGEIF('GPUs Products'!F$9:F$616,GPUs!F12,'GPUs Products'!S$9:S$616) -> 15 | T12: =AVERAGEIF('GPUs Products'!F$9:F$616,GPUs!F12,'GPUs Products'!T$9:T$616) -> 170 | U12: 1x 8-Pin PCIe | V12: 4 | W12: 16 | X12: 16 | Y12: =AVERAGEIF('GPUs Products'!F$9:F$616,GPUs!F12,'GPUs Products'!Y$9:Y$616) -> 532.95348 | Z12: =AVERAGEIF('GPUs Products'!F$9:F$616,GPUs!F12,'GPUs Products'!Y$9:Y$616) -> 532.95348 | AC12: {=(SUMPRODUCT((H12:O12/H$9:O$9)^H$7:O$7*H$2:O$2)+SUMPRODUCT((Q12:T12/Q$9:T$9)^Q$7:T$7*Q$2:T$2))*(0.8^(1-G12))*AC$9} -> 1.3858531 | AD12: {=(SUMPRODUCT((H12:O12/H$9:O$9)^H$7:O$7*H$3:O$3)+SUMPRODUCT((Q12:T12/Q$9:T$9)^Q$7:T$7*Q$3:T$3))*(0.1^(1-G12))*AD$9} -> 1.6292382 | AE12: {=(SUMPRODUCT((H12:O12/H$9:O$9)^H$7:O$7*H$4:O$4)+SUMPRODUCT((Q12:T12/Q$9:T$9)^Q$7:T$7*Q$4:T$4))*AE$9} -> 1.4876803 | AF12: {=(SUMPRODUCT((H12:O12/H$9:O$9)^H$7:O$7*H$5:O$5)+SUMPRODUCT((Q12:T12/Q$9:T$9)^Q$7:T$7*Q$5:T$5))*AF$9} -> 1.3891933 | AG12: {=SUMPRODUCT(AC12:AF12 * AC$3:AF$3) / SUM(AC$3:AF$3)} -> 1.5329379
A13: NVIDIA GeForce RTX 3060 Ti 8GB | C13: NVIDIA | E13: RTX 3000 | F13: 3060 Ti 8GB | G13: 1 | H13: =AVERAGEIF('GPUs Products'!F$9:F$616,GPUs!F13,'GPUs Products'!H$9:H$616) -> 16.795 | I13: =AVERAGEIF('GPUs Products'!F$9:F$616,GPUs!F13,'GPUs Products'!I$9:I$616) -> 16.795 | J13: =AVERAGEIF('GPUs Products'!F$9:F$616,GPUs!F13,'GPUs Products'!J$9:J$616) -> 0.263 | K13: =AVERAGEIF('GPUs Products'!F$9:F$616,GPUs!F13,'GPUs Products'!K$9:K$616) -> 1553.3 | L13: =AVERAGEIF('GPUs Products'!F$9:F$616,GPUs!F13,'GPUs Products'!L$9:L$616) -> 1726.5 | M13: =AVERAGEIF('GPUs Products'!F$9:F$616,GPUs!F13,'GPUs Products'!M$9:M$616) -> 112.8 | N13: =AVERAGEIF('GPUs Products'!F$9:F$616,GPUs!F13,'GPUs Products'!N$9:N$616) -> 214.3 | O13: =AVERAGEIF('GPUs Products'!F$9:F$616,GPUs!F13,'GPUs Products'!O$9:O$616) -> 38 | P13: GDDR6X | Q13: =AVERAGEIF('GPUs Products'!F$9:F$616,GPUs!F13,'GPUs Products'!Q$9:Q$616) -> 8 | R13: =AVERAGEIF('GPUs Products'!F$9:F$616,GPUs!F13,'GPUs Products'!R$9:R$616) -> 256 | S13: =AVERAGEIF('GPUs Products'!F$9:F$616,GPUs!F13,'GPUs Products'!S$9:S$616) -> 15.75 | T13: =AVERAGEIF('GPUs Products'!F$9:F$616,GPUs!F13,'GPUs Products'!T$9:T$616) -> 203 | U13: 2x 8-Pin PCIe | V13: 4 | W13: 16 | X13: 16 | Y13: =AVERAGEIF('GPUs Products'!F$9:F$616,GPUs!F13,'GPUs Products'!Y$9:Y$616) -> 810.904 | Z13: =AVERAGEIF('GPUs Products'!F$9:F$616,GPUs!F13,'GPUs Products'!Y$9:Y$616) -> 810.904 | AC13: {=(SUMPRODUCT((H13:O13/H$9:O$9)^H$7:O$7*H$2:O$2)+SUMPRODUCT((Q13:T13/Q$9:T$9)^Q$7:T$7*Q$2:T$2))*(0.8^(1-G13))*AC$9} -> 1.6550786 | AD13: {=(SUMPRODUCT((H13:O13/H$9:O$9)^H$7:O$7*H$3:O$3)+SUMPRODUCT((Q13:T13/Q$9:T$9)^Q$7:T$7*Q$3:T$3))*(0.1^(1-G13))*AD$9} -> 1.8187127 | AE13: {=(SUMPRODUCT((H13:O13/H$9:O$9)^H$7:O$7*H$4:O$4)+SUMPRODUCT((Q13:T13/Q$9:T$9)^Q$7:T$7*Q$4:T$4))*AE$9} -> 1.6873786 | AF13: {=(SUMPRODUCT((H13:O13/H$9:O$9)^H$7:O$7*H$5:O$5)+SUMPRODUCT((Q13:T13/Q$9:T$9)^Q$7:T$7*Q$5:T$5))*AF$9} -> 1.6418712 | AG13: {=SUMPRODUCT(AC13:AF13 * AC$3:AF$3) / SUM(AC$3:AF$3)} -> 1.7473741
A14: NVIDIA GeForce RTX 3070 8GB | C14: NVIDIA | E14: RTX 3000 | F14: 3070 8GB | G14: 1 | H14: =AVERAGEIF('GPUs Products'!F$9:F$616,GPUs!F14,'GPUs Products'!H$9:H$616) -> 21.062857 | I14: =AVERAGEIF('GPUs Products'!F$9:F$616,GPUs!F14,'GPUs Products'!I$9:I$616) -> 21.062857 | J14: =AVERAGEIF('GPUs Products'!F$9:F$616,GPUs!F14,'GPUs Products'!J$9:J$616) -> 0.32857143 | K14: =AVERAGEIF('GPUs Products'!F$9:F$616,GPUs!F14,'GPUs Products'!K$9:K$616) -> 1750 | L14: =AVERAGEIF('GPUs Products'!F$9:F$616,GPUs!F14,'GPUs Products'!L$9:L$616) -> 1788.5714 | M14: =AVERAGEIF('GPUs Products'!F$9:F$616,GPUs!F14,'GPUs Products'!M$9:M$616) -> 144 | N14: =AVERAGEIF('GPUs Products'!F$9:F$616,GPUs!F14,'GPUs Products'!N$9:N$616) -> 276 | O14: =AVERAGEIF('GPUs Products'!F$9:F$616,GPUs!F14,'GPUs Products'!O$9:O$616) -> 46 | P14: GDDR6 | Q14: =AVERAGEIF('GPUs Products'!F$9:F$616,GPUs!F14,'GPUs Products'!Q$9:Q$616) -> 8 | R14: =AVERAGEIF('GPUs Products'!F$9:F$616,GPUs!F14,'GPUs Products'!R$9:R$616) -> 256 | S14: =AVERAGEIF('GPUs Products'!F$9:F$616,GPUs!F14,'GPUs Products'!S$9:S$616) -> 14 | T14: =AVERAGEIF('GPUs Products'!F$9:F$616,GPUs!F14,'GPUs Products'!T$9:T$616) -> 220.95238 | U14: 2x 8-Pin PCIe | V14: 4 | W14: 16 | X14: 16 | Y14: =AVERAGEIF('GPUs Products'!F$9:F$616,GPUs!F14,'GPUs Products'!Y$9:Y$616) -> 875.28476 | Z14: =AVERAGEIF('GPUs Products'!F$9:F$616,GPUs!F14,'GPUs Products'!Y$9:Y$616) -> 875.28476 | AC14: {=(SUMPRODUCT((H14:O14/H$9:O$9)^H$7:O$7*H$2:O$2)+SUMPRODUCT((Q14:T14/Q$9:T$9)^Q$7:T$7*Q$2:T$2))*(0.8^(1-G14))*AC$9} -> 1.8436812 | AD14: {=(SUMPRODUCT((H14:O14/H$9:O$9)^H$7:O$7*H$3:O$3)+SUMPRODUCT((Q14:T14/Q$9:T$9)^Q$7:T$7*Q$3:T$3))*(0.1^(1-G14))*AD$9} -> 2.0763014 | AE14: {=(SUMPRODUCT((H14:O14/H$9:O$9)^H$7:O$7*H$4:O$4)+SUMPRODUCT((Q14:T14/Q$9:T$9)^Q$7:T$7*Q$4:T$4))*AE$9} -> 1.8955032 | AF14: {=(SUMPRODUCT((H14:O14/H$9:O$9)^H$7:O$7*H$5:O$5)+SUMPRODUCT((Q14:T14/Q$9:T$9)^Q$7:T$7*Q$5:T$5))*AF$9} -> 1.8574326 | AG14: {=SUMPRODUCT(AC14:AF14 * AC$3:AF$3) / SUM(AC$3:AF$3)} -> 1.9809646
A15: NVIDIA GeForce RTX 3070 Ti 8GB | C15: NVIDIA | E15: RTX 3000 | F15: 3070 Ti 8GB | G15: 1 | H15: =AVERAGEIF('GPUs Products'!F$9:F$616,GPUs!F15,'GPUs Products'!H$9:H$616) -> 22.256875 | I15: =AVERAGEIF('GPUs Products'!F$9:F$616,GPUs!F15,'GPUs Products'!I$9:I$616) -> 22.256875 | J15: =AVERAGEIF('GPUs Products'!F$9:F$616,GPUs!F15,'GPUs Products'!J$9:J$616) -> 0.348125 | K15: =AVERAGEIF('GPUs Products'!F$9:F$616,GPUs!F15,'GPUs Products'!K$9:K$616) -> 1188 | L15: =AVERAGEIF('GPUs Products'!F$9:F$616,GPUs!F15,'GPUs Products'!L$9:L$616) -> 1811.25 | M15: =AVERAGEIF('GPUs Products'!F$9:F$616,GPUs!F15,'GPUs Products'!M$9:M$616) -> 151.6 | N15: =AVERAGEIF('GPUs Products'!F$9:F$616,GPUs!F15,'GPUs Products'!N$9:N$616) -> 303.3 | O15: =AVERAGEIF('GPUs Products'!F$9:F$616,GPUs!F15,'GPUs Products'!O$9:O$616) -> 48 | P15: GDDR6X | Q15: =AVERAGEIF('GPUs Products'!F$9:F$616,GPUs!F15,'GPUs Products'!Q$9:Q$616) -> 8 | R15: =AVERAGEIF('GPUs Products'!F$9:F$616,GPUs!F15,'GPUs Products'!R$9:R$616) -> 256 | S15: =AVERAGEIF('GPUs Products'!F$9:F$616,GPUs!F15,'GPUs Products'!S$9:S$616) -> 19 | T15: =AVERAGEIF('GPUs Products'!F$9:F$616,GPUs!F15,'GPUs Products'!T$9:T$616) -> 291.25 | U15: 2x 8-Pin PCIe | V15: 4 | W15: 16 | X15: 16 | Y15: =AVERAGEIF('GPUs Products'!F$9:F$616,GPUs!F15,'GPUs Products'!Y$9:Y$616) -> 919.61187 | Z15: =AVERAGEIF('GPUs Products'!F$9:F$616,GPUs!F15,'GPUs Products'!Y$9:Y$616) -> 919.61187 | AC15: {=(SUMPRODUCT((H15:O15/H$9:O$9)^H$7:O$7*H$2:O$2)+SUMPRODUCT((Q15:T15/Q$9:T$9)^Q$7:T$7*Q$2:T$2))*(0.8^(1-G15))*AC$9} -> 1.8809647 | AD15: {=(SUMPRODUCT((H15:O15/H$9:O$9)^H$7:O$7*H$3:O$3)+SUMPRODUCT((Q15:T15/Q$9:T$9)^Q$7:T$7*Q$3:T$3))*(0.1^(1-G15))*AD$9} -> 2.1433335 | AE15: {=(SUMPRODUCT((H15:O15/H$9:O$9)^H$7:O$7*H$4:O$4)+SUMPRODUCT((Q15:T15/Q$9:T$9)^Q$7:T$7*Q$4:T$4))*AE$9} -> 1.9691625 | AF15: {=(SUMPRODUCT((H15:O15/H$9:O$9)^H$7:O$7*H$5:O$5)+SUMPRODUCT((Q15:T15/Q$9:T$9)^Q$7:T$7*Q$5:T$5))*AF$9} -> 1.9144807 | AG15: {=SUMPRODUCT(AC15:AF15 * AC$3:AF$3) / SUM(AC$3:AF$3)} -> 2.0421109
A16: NVIDIA GeForce RTX 3080 10GB | C16: NVIDIA | E16: RTX 3000 | F16: 3080 10GB | G16: 1 | H16: =AVERAGEIF('GPUs Products'!F$9:F$616,GPUs!F16,'GPUs Products'!H$9:H$616) -> 31.494615 | I16: =AVERAGEIF('GPUs Products'!F$9:F$616,GPUs!F16,'GPUs Products'!I$9:I$616) -> 31.494615 | J16: =AVERAGEIF('GPUs Products'!F$9:F$616,GPUs!F16,'GPUs Products'!J$9:J$616) -> 0.49230769 | K16: =AVERAGEIF('GPUs Products'!F$9:F$616,GPUs!F16,'GPUs Products'!K$9:K$616) -> 1188 | L16: =AVERAGEIF('GPUs Products'!F$9:F$616,GPUs!F16,'GPUs Products'!L$9:L$616) -> 1809.2308 | M16: =AVERAGEIF('GPUs Products'!F$9:F$616,GPUs!F16,'GPUs Products'!M$9:M$616) -> 138.2 | N16: =AVERAGEIF('GPUs Products'!F$9:F$616,GPUs!F16,'GPUs Products'!N$9:N$616) -> 391.7 | O16: =AVERAGEIF('GPUs Products'!F$9:F$616,GPUs!F16,'GPUs Products'!O$9:O$616) -> 68 | P16: GDDR6X | Q16: =AVERAGEIF('GPUs Products'!F$9:F$616,GPUs!F16,'GPUs Products'!Q$9:Q$616) -> 10 | R16: =AVERAGEIF('GPUs Products'!F$9:F$616,GPUs!F16,'GPUs Products'!R$9:R$616) -> 320 | S16: =AVERAGEIF('GPUs Products'!F$9:F$616,GPUs!F16,'GPUs Products'!S$9:S$616) -> 19 | T16: =AVERAGEIF('GPUs Products'!F$9:F$616,GPUs!F16,'GPUs Products'!T$9:T$616) -> 327.69231 | U16: 3x 8-Pin PCIe | V16: 4 | W16: 16 | X16: 16 | Y16: =AVERAGEIF('GPUs Products'!F$9:F$616,GPUs!F16,'GPUs Products'!Y$9:Y$616) -> 1266.1462 | Z16: =AVERAGEIF('GPUs Products'!F$9:F$616,GPUs!F16,'GPUs Products'!Y$9:Y$616) -> 1266.1462 | AC16: {=(SUMPRODUCT((H16:O16/H$9:O$9)^H$7:O$7*H$2:O$2)+SUMPRODUCT((Q16:T16/Q$9:T$9)^Q$7:T$7*Q$2:T$2))*(0.8^(1-G16))*AC$9} -> 2.1059773 | AD16: {=(SUMPRODUCT((H16:O16/H$9:O$9)^H$7:O$7*H$3:O$3)+SUMPRODUCT((Q16:T16/Q$9:T$9)^Q$7:T$7*Q$3:T$3))*(0.1^(1-G16))*AD$9} -> 2.7492747 | AE16: {=(SUMPRODUCT((H16:O16/H$9:O$9)^H$7:O$7*H$4:O$4)+SUMPRODUCT((Q16:T16/Q$9:T$9)^Q$7:T$7*Q$4:T$4))*AE$9} -> 2.4941368 | AF16: {=(SUMPRODUCT((H16:O16/H$9:O$9)^H$7:O$7*H$5:O$5)+SUMPRODUCT((Q16:T16/Q$9:T$9)^Q$7:T$7*Q$5:T$5))*AF$9} -> 2.3188878 | AG16: {=SUMPRODUCT(AC16:AF16 * AC$3:AF$3) / SUM(AC$3:AF$3)} -> 2.5419786
A17: NVIDIA GeForce RTX 3080 12GB | C17: NVIDIA | E17: RTX 3000 | F17: 3080 12GB | G17: 1 | H17: =AVERAGEIF('GPUs Products'!F$9:F$616,GPUs!F17,'GPUs Products'!H$9:H$616) -> 32.5925 | I17: =AVERAGEIF('GPUs Products'!F$9:F$616,GPUs!F17,'GPUs Products'!I$9:I$616) -> 32.5925 | J17: =AVERAGEIF('GPUs Products'!F$9:F$616,GPUs!F17,'GPUs Products'!J$9:J$616) -> 0.51 | K17: =AVERAGEIF('GPUs Products'!F$9:F$616,GPUs!F17,'GPUs Products'!K$9:K$616) -> 1188 | L17: =AVERAGEIF('GPUs Products'!F$9:F$616,GPUs!F17,'GPUs Products'!L$9:L$616) -> 1818.75 | M17: =AVERAGEIF('GPUs Products'!F$9:F$616,GPUs!F17,'GPUs Products'!M$9:M$616) -> 152.8 | N17: =AVERAGEIF('GPUs Products'!F$9:F$616,GPUs!F17,'GPUs Products'!N$9:N$616) -> 436.8 | O17: =AVERAGEIF('GPUs Products'!F$9:F$616,GPUs!F17,'GPUs Products'!O$9:O$616) -> 70 | P17: GDDR6X | Q17: =AVERAGEIF('GPUs Products'!F$9:F$616,GPUs!F17,'GPUs Products'!Q$9:Q$616) -> 12 | R17: =AVERAGEIF('GPUs Products'!F$9:F$616,GPUs!F17,'GPUs Products'!R$9:R$616) -> 384 | S17: =AVERAGEIF('GPUs Products'!F$9:F$616,GPUs!F17,'GPUs Products'!S$9:S$616) -> 19 | T17: =AVERAGEIF('GPUs Products'!F$9:F$616,GPUs!F17,'GPUs Products'!T$9:T$616) -> 350 | U17: 3x 8-Pin PCIe | V17: 4 | W17: 16 | X17: 16 | Y17: =AVERAGEIF('GPUs Products'!F$9:F$616,GPUs!F17,'GPUs Products'!Y$9:Y$616) -> 2016.5975 | Z17: =AVERAGEIF('GPUs Products'!F$9:F$616,GPUs!F17,'GPUs Products'!Y$9:Y$616) -> 2016.5975 | AC17: {=(SUMPRODUCT((H17:O17/H$9:O$9)^H$7:O$7*H$2:O$2)+SUMPRODUCT((Q17:T17/Q$9:T$9)^Q$7:T$7*Q$2:T$2))*(0.8^(1-G17))*AC$9} -> 2.2419446 | AD17: {=(SUMPRODUCT((H17:O17/H$9:O$9)^H$7:O$7*H$3:O$3)+SUMPRODUCT((Q17:T17/Q$9:T$9)^Q$7:T$7*Q$3:T$3))*(0.1^(1-G17))*AD$9} -> 2.8818209 | AE17: {=(SUMPRODUCT((H17:O17/H$9:O$9)^H$7:O$7*H$4:O$4)+SUMPRODUCT((Q17:T17/Q$9:T$9)^Q$7:T$7*Q$4:T$4))*AE$9} -> 2.6264371 | AF17: {=(SUMPRODUCT((H17:O17/H$9:O$9)^H$7:O$7*H$5:O$5)+SUMPRODUCT((Q17:T17/Q$9:T$9)^Q$7:T$7*Q$5:T$5))*AF$9} -> 2.4433438 | AG17: {=SUMPRODUCT(AC17:AF17 * AC$3:AF$3) / SUM(AC$3:AF$3)} -> 2.6737193
A18: NVIDIA GeForce RTX 3080 Ti 12GB | C18: NVIDIA | E18: RTX 3000 | F18: 3080 Ti 12GB | G18: 1 | H18: =AVERAGEIF('GPUs Products'!F$9:F$616,GPUs!F18,'GPUs Products'!H$9:H$616) -> 35.113 | I18: =AVERAGEIF('GPUs Products'!F$9:F$616,GPUs!F18,'GPUs Products'!I$9:I$616) -> 35.113 | J18: =AVERAGEIF('GPUs Products'!F$9:F$616,GPUs!F18,'GPUs Products'!J$9:J$616) -> 0.549 | K18: =AVERAGEIF('GPUs Products'!F$9:F$616,GPUs!F18,'GPUs Products'!K$9:K$616) -> 1188 | L18: =AVERAGEIF('GPUs Products'!F$9:F$616,GPUs!F18,'GPUs Products'!L$9:L$616) -> 1714.5 | M18: =AVERAGEIF('GPUs Products'!F$9:F$616,GPUs!F18,'GPUs Products'!M$9:M$616) -> 152.8 | N18: =AVERAGEIF('GPUs Products'!F$9:F$616,GPUs!F18,'GPUs Products'!N$9:N$616) -> 478.8 | O18: =AVERAGEIF('GPUs Products'!F$9:F$616,GPUs!F18,'GPUs Products'!O$9:O$616) -> 80 | P18: GDDR6X | Q18: =AVERAGEIF('GPUs Products'!F$9:F$616,GPUs!F18,'GPUs Products'!Q$9:Q$616) -> 12 | R18: =AVERAGEIF('GPUs Products'!F$9:F$616,GPUs!F18,'GPUs Products'!R$9:R$616) -> 384 | S18: =AVERAGEIF('GPUs Products'!F$9:F$616,GPUs!F18,'GPUs Products'!S$9:S$616) -> 19 | T18: =AVERAGEIF('GPUs Products'!F$9:F$616,GPUs!F18,'GPUs Products'!T$9:T$616) -> 350 | U18: 3x 8-Pin PCIe | V18: 4 | W18: 16 | X18: 16 | Y18: =AVERAGEIF('GPUs Products'!F$9:F$616,GPUs!F18,'GPUs Products'!Y$9:Y$616) -> 1838.842 | Z18: =AVERAGEIF('GPUs Products'!F$9:F$616,GPUs!F18,'GPUs Products'!Y$9:Y$616) -> 1838.842 | AC18: {=(SUMPRODUCT((H18:O18/H$9:O$9)^H$7:O$7*H$2:O$2)+SUMPRODUCT((Q18:T18/Q$9:T$9)^Q$7:T$7*Q$2:T$2))*(0.8^(1-G18))*AC$9} -> 2.309644 | AD18: {=(SUMPRODUCT((H18:O18/H$9:O$9)^H$7:O$7*H$3:O$3)+SUMPRODUCT((Q18:T18/Q$9:T$9)^Q$7:T$7*Q$3:T$3))*(0.1^(1-G18))*AD$9} -> 3.019624 | AE18: {=(SUMPRODUCT((H18:O18/H$9:O$9)^H$7:O$7*H$4:O$4)+SUMPRODUCT((Q18:T18/Q$9:T$9)^Q$7:T$7*Q$4:T$4))*AE$9} -> 2.7412251 | AF18: {=(SUMPRODUCT((H18:O18/H$9:O$9)^H$7:O$7*H$5:O$5)+SUMPRODUCT((Q18:T18/Q$9:T$9)^Q$7:T$7*Q$5:T$5))*AF$9} -> 2.5555121 | AG18: {=SUMPRODUCT(AC18:AF18 * AC$3:AF$3) / SUM(AC$3:AF$3)} -> 2.7930088
A19: NVIDIA GeForce RTX 3090 24GB | C19: NVIDIA | E19: RTX 3000 | F19: 3090 24GB | G19: 1 | H19: =AVERAGEIF('GPUs Products'!F$9:F$616,GPUs!F19,'GPUs Products'!H$9:H$616) -> 37.103333 | I19: =AVERAGEIF('GPUs Products'!F$9:F$616,GPUs!F19,'GPUs Products'!I$9:I$616) -> 37.103333 | J19: =AVERAGEIF('GPUs Products'!F$9:F$616,GPUs!F19,'GPUs Products'!J$9:J$616) -> 0.5825 | K19: =AVERAGEIF('GPUs Products'!F$9:F$616,GPUs!F19,'GPUs Products'!K$9:K$616) -> 1219 | L19: =AVERAGEIF('GPUs Products'!F$9:F$616,GPUs!F19,'GPUs Products'!L$9:L$616) -> 1767.5 | M19: =AVERAGEIF('GPUs Products'!F$9:F$616,GPUs!F19,'GPUs Products'!M$9:M$616) -> 189.9 | N19: =AVERAGEIF('GPUs Products'!F$9:F$616,GPUs!F19,'GPUs Products'!N$9:N$616) -> 556 | O19: =AVERAGEIF('GPUs Products'!F$9:F$616,GPUs!F19,'GPUs Products'!O$9:O$616) -> 82 | P19: GDDR6X | Q19: =AVERAGEIF('GPUs Products'!F$9:F$616,GPUs!F19,'GPUs Products'!Q$9:Q$616) -> 24 | R19: =AVERAGEIF('GPUs Products'!F$9:F$616,GPUs!F19,'GPUs Products'!R$9:R$616) -> 384 | S19: =AVERAGEIF('GPUs Products'!F$9:F$616,GPUs!F19,'GPUs Products'!S$9:S$616) -> 19.5 | T19: =AVERAGEIF('GPUs Products'!F$9:F$616,GPUs!F19,'GPUs Products'!T$9:T$616) -> 357.5 | U19: 3x 8-Pin PCIe | V19: 4 | W19: 16 | X19: 16 | Y19: =AVERAGEIF('GPUs Products'!F$9:F$616,GPUs!F19,'GPUs Products'!Y$9:Y$616) -> 2364.9017 | Z19: =AVERAGEIF('GPUs Products'!F$9:F$616,GPUs!F19,'GPUs Products'!Y$9:Y$616) -> 2364.9017 | AC19: {=(SUMPRODUCT((H19:O19/H$9:O$9)^H$7:O$7*H$2:O$2)+SUMPRODUCT((Q19:T19/Q$9:T$9)^Q$7:T$7*Q$2:T$2))*(0.8^(1-G19))*AC$9} -> 2.5673091 | AD19: {=(SUMPRODUCT((H19:O19/H$9:O$9)^H$7:O$7*H$3:O$3)+SUMPRODUCT((Q19:T19/Q$9:T$9)^Q$7:T$7*Q$3:T$3))*(0.1^(1-G19))*AD$9} -> 3.3122284 | AE19: {=(SUMPRODUCT((H19:O19/H$9:O$9)^H$7:O$7*H$4:O$4)+SUMPRODUCT((Q19:T19/Q$9:T$9)^Q$7:T$7*Q$4:T$4))*AE$9} -> 2.9733348 | AF19: {=(SUMPRODUCT((H19:O19/H$9:O$9)^H$7:O$7*H$5:O$5)+SUMPRODUCT((Q19:T19/Q$9:T$9)^Q$7:T$7*Q$5:T$5))*AF$9} -> 2.7812954 | AG19: {=SUMPRODUCT(AC19:AF19 * AC$3:AF$3) / SUM(AC$3:AF$3)} -> 3.0619315
A20: NVIDIA GeForce RTX 3090 Ti 24GB | C20: NVIDIA | E20: RTX 3000 | F20: 3090 Ti 24GB | G20: 1 | H20: =AVERAGEIF('GPUs Products'!F$9:F$616,GPUs!F20,'GPUs Products'!H$9:H$616) -> 41.6125 | I20: =AVERAGEIF('GPUs Products'!F$9:F$616,GPUs!F20,'GPUs Products'!I$9:I$616) -> 41.6125 | J20: =AVERAGEIF('GPUs Products'!F$9:F$616,GPUs!F20,'GPUs Products'!J$9:J$616) -> 0.6525 | K20: =AVERAGEIF('GPUs Products'!F$9:F$616,GPUs!F20,'GPUs Products'!K$9:K$616) -> 1313 | L20: =AVERAGEIF('GPUs Products'!F$9:F$616,GPUs!F20,'GPUs Products'!L$9:L$616) -> 1935 | M20: =AVERAGEIF('GPUs Products'!F$9:F$616,GPUs!F20,'GPUs Products'!M$9:M$616) -> 174.7 | N20: =AVERAGEIF('GPUs Products'!F$9:F$616,GPUs!F20,'GPUs Products'!N$9:N$616) -> 524.1 | O20: =AVERAGEIF('GPUs Products'!F$9:F$616,GPUs!F20,'GPUs Products'!O$9:O$616) -> 84 | P20: GDDR6X | Q20: =AVERAGEIF('GPUs Products'!F$9:F$616,GPUs!F20,'GPUs Products'!Q$9:Q$616) -> 24 | R20: =AVERAGEIF('GPUs Products'!F$9:F$616,GPUs!F20,'GPUs Products'!R$9:R$616) -> 384 | S20: =AVERAGEIF('GPUs Products'!F$9:F$616,GPUs!F20,'GPUs Products'!S$9:S$616) -> 21 | T20: =AVERAGEIF('GPUs Products'!F$9:F$616,GPUs!F20,'GPUs Products'!T$9:T$616) -> 457.5 | U20: 1x 12VHPWR (via Adapter: 3x 8-Pin PCIe) | V20: 4 | W20: 16 | X20: 16 | Y20: =AVERAGEIF('GPUs Products'!F$9:F$616,GPUs!F20,'GPUs Products'!Y$9:Y$616) -> 2462.8075 | Z20: =AVERAGEIF('GPUs Products'!F$9:F$616,GPUs!F20,'GPUs Products'!Y$9:Y$616) -> 2462.8075 | AC20: {=(SUMPRODUCT((H20:O20/H$9:O$9)^H$7:O$7*H$2:O$2)+SUMPRODUCT((Q20:T20/Q$9:T$9)^Q$7:T$7*Q$2:T$2))*(0.8^(1-G20))*AC$9} -> 2.57555 | AD20: {=(SUMPRODUCT((H20:O20/H$9:O$9)^H$7:O$7*H$3:O$3)+SUMPRODUCT((Q20:T20/Q$9:T$9)^Q$7:T$7*Q$3:T$3))*(0.1^(1-G20))*AD$9} -> 3.5667961 | AE20: {=(SUMPRODUCT((H20:O20/H$9:O$9)^H$7:O$7*H$4:O$4)+SUMPRODUCT((Q20:T20/Q$9:T$9)^Q$7:T$7*Q$4:T$4))*AE$9} -> 3.1845147 | AF20: {=(SUMPRODUCT((H20:O20/H$9:O$9)^H$7:O$7*H$5:O$5)+SUMPRODUCT((Q20:T20/Q$9:T$9)^Q$7:T$7*Q$5:T$5))*AF$9} -> 2.8986649 | AG20: {=SUMPRODUCT(AC20:AF20 * AC$3:AF$3) / SUM(AC$3:AF$3)} -> 3.2477575
A21: NVIDIA GeForce RTX 4060 8GB | C21: NVIDIA | E21: RTX 4000 | F21: 4060 8GB | G21: 1 | H21: =AVERAGEIF('GPUs Products'!F$9:F$616,GPUs!F21,'GPUs Products'!H$9:H$616) -> 15.450513 | I21: =AVERAGEIF('GPUs Products'!F$9:F$616,GPUs!F21,'GPUs Products'!I$9:I$616) -> 15.450513 | J21: =AVERAGEIF('GPUs Products'!F$9:F$616,GPUs!F21,'GPUs Products'!J$9:J$616) -> 0.24179487 | K21: =AVERAGEIF('GPUs Products'!F$9:F$616,GPUs!F21,'GPUs Products'!K$9:K$616) -> 2125 | L21: =AVERAGEIF('GPUs Products'!F$9:F$616,GPUs!F21,'GPUs Products'!L$9:L$616) -> 2513.8462 | M21: =AVERAGEIF('GPUs Products'!F$9:F$616,GPUs!F21,'GPUs Products'!M$9:M$616) -> 58.6 | N21: =AVERAGEIF('GPUs Products'!F$9:F$616,GPUs!F21,'GPUs Products'!N$9:N$616) -> 175.7 | O21: =AVERAGEIF('GPUs Products'!F$9:F$616,GPUs!F21,'GPUs Products'!O$9:O$616) -> 24 | P21: GDDR6 | Q21: =AVERAGEIF('GPUs Products'!F$9:F$616,GPUs!F21,'GPUs Products'!Q$9:Q$616) -> 8 | R21: =AVERAGEIF('GPUs Products'!F$9:F$616,GPUs!F21,'GPUs Products'!R$9:R$616) -> 128 | S21: =AVERAGEIF('GPUs Products'!F$9:F$616,GPUs!F21,'GPUs Products'!S$9:S$616) -> 17 | T21: =AVERAGEIF('GPUs Products'!F$9:F$616,GPUs!F21,'GPUs Products'!T$9:T$616) -> 115 | U21: 1x 8-Pin PCIe | V21: 4 | W21: 16 | X21: 8 | Y21: =AVERAGEIF('GPUs Products'!F$9:F$616,GPUs!F21,'GPUs Products'!Y$9:Y$616) -> 431.66051 | Z21: =AVERAGEIF('GPUs Products'!F$9:F$616,GPUs!F21,'GPUs Products'!Y$9:Y$616) -> 431.66051 | AC21: {=(SUMPRODUCT((H21:O21/H$9:O$9)^H$7:O$7*H$2:O$2)+SUMPRODUCT((Q21:T21/Q$9:T$9)^Q$7:T$7*Q$2:T$2))*(0.8^(1-G21))*AC$9} -> 1.5126208 | AD21: {=(SUMPRODUCT((H21:O21/H$9:O$9)^H$7:O$7*H$3:O$3)+SUMPRODUCT((Q21:T21/Q$9:T$9)^Q$7:T$7*Q$3:T$3))*(0.1^(1-G21))*AD$9} -> 1.6988457 | AE21: {=(SUMPRODUCT((H21:O21/H$9:O$9)^H$7:O$7*H$4:O$4)+SUMPRODUCT((Q21:T21/Q$9:T$9)^Q$7:T$7*Q$4:T$4))*AE$9} -> 1.5120286 | AF21: {=(SUMPRODUCT((H21:O21/H$9:O$9)^H$7:O$7*H$5:O$5)+SUMPRODUCT((Q21:T21/Q$9:T$9)^Q$7:T$7*Q$5:T$5))*AF$9} -> 1.4726372 | AG21: {=SUMPRODUCT(AC21:AF21 * AC$3:AF$3) / SUM(AC$3:AF$3)} -> 1.6093493
... A56: AMD Radeon RX 7900 XTX 24GB | C56: AMD | E56: RX 7000 | F56: 7900 XTX 24GB | G56: 0 | H56: =AVERAGEIF('GPUs Products'!F$9:F$616,GPUs!F56,'GPUs Products'!H$9:H$616) -> 127.05667 | I56: =AVERAGEIF('GPUs Products'!F$9:F$616,GPUs!F56,'GPUs Products'!I$9:I$616) -> 63.53 | J56: =AVERAGEIF('GPUs Products'!F$9:F$616,GPUs!F56,'GPUs Products'!J$9:J$616) -> 3.9733333 | K56: =AVERAGEIF('GPUs Products'!F$9:F$616,GPUs!F56,'GPUs Products'!K$9:K$616) -> 2500 | L56: =AVERAGEIF('GPUs Products'!F$9:F$616,GPUs!F56,'GPUs Products'!L$9:L$616) -> 2585 | M56: =AVERAGEIF('GPUs Products'!F$9:F$616,GPUs!F56,'GPUs Products'!M$9:M$616) -> 480 | N56: =AVERAGEIF('GPUs Products'!F$9:F$616,GPUs!F56,'GPUs Products'!N$9:N$616) -> 960 | O56: =AVERAGEIF('GPUs Products'!F$9:F$616,GPUs!F56,'GPUs Products'!O$9:O$616) -> 96 | P56: GDDR6 | Q56: =AVERAGEIF('GPUs Products'!F$9:F$616,GPUs!F56,'GPUs Products'!Q$9:Q$616) -> 24 | R56: =AVERAGEIF('GPUs Products'!F$9:F$616,GPUs!F56,'GPUs Products'!R$9:R$616) -> 384 | S56: =AVERAGEIF('GPUs Products'!F$9:F$616,GPUs!F56,'GPUs Products'!S$9:S$616) -> 20 | T56: =AVERAGEIF('GPUs Products'!F$9:F$616,GPUs!F56,'GPUs Products'!T$9:T$616) -> 355 | U56: 3x 8-Pin PCIe | V56: 4 | W56: 16 | X56: 16 | Y56: =AVERAGEIF('GPUs Products'!F$9:F$616,GPUs!F56,'GPUs Products'!Y$9:Y$616) -> 1235.2533 | Z56: =AVERAGEIF('GPUs Products'!F$9:F$616,GPUs!F56,'GPUs Products'!Y$9:Y$616) -> 1235.2533 | AC56: {=(SUMPRODUCT((H56:O56/H$9:O$9)^H$7:O$7*H$2:O$2)+SUMPRODUCT((Q56:T56/Q$9:T$9)^Q$7:T$7*Q$2:T$2))*(0.8^(1-G56))*AC$9} -> 3.0445355 | AD56: {=(SUMPRODUCT((H56:O56/H$9:O$9)^H$7:O$7*H$3:O$3)+SUMPRODUCT((Q56:T56/Q$9:T$9)^Q$7:T$7*Q$3:T$3))*(0.1^(1-G56))*AD$9} -> 0.69542437 | AE56: {=(SUMPRODUCT((H56:O56/H$9:O$9)^H$7:O$7*H$4:O$4)+SUMPRODUCT((Q56:T56/Q$9:T$9)^Q$7:T$7*Q$4:T$4))*AE$9} -> 8.2773892 | AF56: {=(SUMPRODUCT((H56:O56/H$9:O$9)^H$7:O$7*H$5:O$5)+SUMPRODUCT((Q56:T56/Q$9:T$9)^Q$7:T$7*Q$5:T$5))*AF$9} -> 4.3142762 | AG56: {=SUMPRODUCT(AC56:AF56 * AC$3:AF$3) / SUM(AC$3:AF$3)} -> 2.5325254

Sheet GPUs Products
A1: GPU Specification Weights per Task | G1: CUDA Ready | H1: FP16 | I1: FP32 | J1: FP64 | K1: Base Clock | L1: Turbo Clock | M1: Pixel Fill Rate | N1: Texture Units | O1: RT Cores | Q1: Memory Capacity | R1: Memory Bus Width | S1: Memory Speed | T1: Power | AC1: Task
A2: Gaming | H2: 0 | I2: 0.05 | J2: 0 | K2: 0.15 | L2: 0.25 | M2: 0.1 | N2: 0.1 | O2: 0.1 | Q2: 0.1 | R2: 0.1 | S2: 0.1 | T2: 0.05 | AC2: Gaming | AD2: ML/AI | AE2: HPC | AF2: 3D Rendering
A3: ML/AI | H3: 0.3 | I3: 0.2 | J3: 0.05 | K3: 0.05 | L3: 0.05 | M3: 0 | N3: 0 | O3: 0 | Q3: 0.2 | R3: 0.1 | S3: 0.05 | T3: 0.05 | AC3: 3 | AD3: 10 | AE3: 2 | AF3: 3
A4: HPC | H4: 0 | I4: 0.15 | J4: 0.35 | K4: 0.05 | L4: 0 | M4: 0 | N4: 0 | O4: 0 | Q4: 0.15 | R4: 0.15 | S4: 0.1 | T4: 0
A5: 3D Rendering | H5: 0.05 | I5: 0.2 | J5: 0 | K5: 0.1 | L5: 0.1 | M5: 0.05 | N5: 0.05 | O5: 0.1 | Q5: 0.1 | R5: 0.1 | S5: 0.1 | T5: 0.05
A7: Scaling Factor | H7: 0.85 | I7: 0.9 | J7: 0.8 | K7: 0.9 | L7: 0.9 | M7: 0.85 | N7: 0.85 | O7: 0.8 | Q7: 0.65 | R7: 0.75 | S7: 0.8 | T7: -0.5
A8: GPU | B8: Code | C8: Brand | D8: Manufacturer | E8: Series | F8: Model | G8: CUDA Ready | H8: FP16 | I8: FP32 | J8: FP64 | K8: Base Clock | L8: Turbo Clock | M8: Pixel Fill Rate | N8: Texture Units | O8: RT Cores | P8: VRAM Type | Q8: Memory Capacity | R8: Memory Bus Width | S8: Memory Speed | T8: Power | U8: Power Connection | V8: PCIe Version | W8: Physical Lanes | X8: Wired Lanes | Y8: Price Min | Z8: Price Max | AA8: Link | AB8: Product | AC8: Gaming Score | AD8: ML/AI Score | AE8: HPC Score | AF8: 3D Rendering Score | AG8: Task Score
A9: ASUS Dual GeForce RTX 3050 OC, DUAL-RTX3050-O6G, 6GB GDDR6, DVI, HDMI, DP | B9: 90YV0K60-M0NA00 | C9: NVIDIA | D9: =LEFT(AB9, FIND(" ", AB9 & " ") - 1) -> ASUS | E9: RTX 3000 | F9: 3050 6GB | G9: 1 | H9: 7.08 | I9: 7.08 | J9: 0.11 | K9: 1750 | L9: 1750 | M9: 33.34 | N9: 75.02 | O9: 20 | P9: GDDR6 | Q9: 6 | R9: 96 | S9: 14 | T9: 70 | U9: - | V9: 4 | W9: 16 | X9: 8 | Y9: 192.9 | Z9: 277 | AA9: https://geizhals.eu/asus-dual-geforce-rtx-3050-oc-90yv0k60-m0na00-a3117139.html?hloc=at&hloc=de&hloc=eu&hloc=pl&hloc=uk | AB9: ASUS Dual GeForce RTX 3050 OC, DUAL-RTX3050-O6G, 6GB GDDR6, DVI, HDMI, DP | AC9: 1 | AD9: 1 | AE9: 1 | AF9: 1 | AG9: {=SUMPRODUCT(AC9:AF9 * AC$3:AF$3) / SUM(AC$3:AF$3)} -> 1
A10: ASUS Dual GeForce RTX 3050, DUAL-RTX3050-6G, 6GB GDDR6, DVI, HDMI, DP | B10: 90YV0K61-M0NA00 | C10: NVIDIA | D10: =LEFT(AB10, FIND(" ", AB10 & " ") - 1) -> ASUS | E10: RTX 3000 | F10: 3050 6GB | G10: 1 | H10: 6.91 | I10: 6.91 | J10: 0.11 | K10: 1750 | L10: 1750 | M10: 33.34 | N10: 75.02 | O10: 20 | P10: GDDR6 | Q10: 6 | R10: 96 | S10: 14 | T10: 70 | U10: - | V10: 4 | W10: 16 | X10: 8 | Y10: 229.03 | Z10: 229.03 | AA10: https://geizhals.eu/asus-dual-geforce-rtx-3050-90yv0k61-m0na00-a3117146.html?hloc=at&hloc=de&hloc=eu&hloc=pl&hloc=uk | AB10: ASUS Dual GeForce RTX 3050, DUAL-RTX3050-6G, 6GB GDDR6, DVI, HDMI, DP | AC10: {=(SUMPRODUCT((H10:O10/H$9:O$9)^H$7:O$7*H$2:O$2)+SUMPRODUCT((Q10:T10/Q$9:T$9)^Q$7:T$7*Q$2:T$2))*(0.8^(1-G10))*AC$9} -> 1.0989182 | AD10: {=(SUMPRODUCT((H10:O10/H$9:O$9)^H$7:O$7*H$3:O$3)+SUMPRODUCT((Q10:T10/Q$9:T$9)^Q$7:T$7*Q$3:T$3))*(0.1^(1-G10))*AD$9} -> 1.0395387 | AE10: {=(SUMPRODUCT((H10:O10/H$9:O$9)^H$7:O$7*H$4:O$4)+SUMPRODUCT((Q10:T10/Q$9:T$9)^Q$7:T$7*Q$4:T$4))*AE$9} -> 0.94675455 | AF10: {=(SUMPRODUCT((H10:O10/H$9:O$9)^H$7:O$7*H$5:O$5)+SUMPRODUCT((Q10:T10/Q$9:T$9)^Q$7:T$7*Q$5:T$5))*AF$9} -> 0.9946504 | AG10: {=SUMPRODUCT(AC10:AF10 * AC$3:AF$3) / SUM(AC$3:AF$3)} -> 1.0316446
A11: ASUS GeForce RTX 3050 OC, RTX3050-O6G-LP-BRK, 6GB GDDR6, DVI, HDMI, DP | B11: 90YV0KQ0-M0NA00 | C11: NVIDIA | D11: =LEFT(AB11, FIND(" ", AB11 & " ") - 1) -> ASUS | E11: RTX 3000 | F11: 3050 6GB | G11: 1 | H11: 7.08 | I11: 7.08 | J11: 0.11 | K11: 1750 | L11: 1750 | M11: 33.34 | N11: 75.02 | O11: 20 | P11: GDDR6 | Q11: 6 | R11: 96 | S11: 14 | T11: 70 | U11: - | V11: 4 | W11: 16 | X11: 8 | Y11: 198.9 | Z11: 274.19 | AA11: https://geizhals.eu/asus-geforce-rtx-3050-oc-a3117233.html?hloc=at&hloc=de&hloc=eu&hloc=pl&hloc=uk | AB11: ASUS GeForce RTX 3050 OC, RTX3050-O6G-LP-BRK, 6GB GDDR6, DVI, HDMI, DP | AC11: {=(SUMPRODUCT((H11:O11/H$9:O$9)^H$7:O$7*H$2:O$2)+SUMPRODUCT((Q11:T11/Q$9:T$9)^Q$7:T$7*Q$2:T$2))*(0.8^(1-G11))*AC$9} -> 1.1 | AD11: {=(SUMPRODUCT((H11:O11/H$9:O$9)^H$7:O$7*H$3:O$3)+SUMPRODUCT((Q11:T11/Q$9:T$9)^Q$7:T$7*Q$3:T$3))*(0.1^(1-G11))*AD$9} -> 1.05 | AE11: {=(SUMPRODUCT((H11:O11/H$9:O$9)^H$7:O$7*H$4:O$4)+SUMPRODUCT((Q11:T11/Q$9:T$9)^Q$7:T$7*Q$4:T$4))*AE$9} -> 0.95 | AF11: {=(SUMPRODUCT((H11:O11/H$9:O$9)^H$7:O$7*H$5:O$5)+SUMPRODUCT((Q11:T11/Q$9:T$9)^Q$7:T$7*Q$5:T$5))*AF$9} -> 1 | AG11: {=SUMPRODUCT(AC11:AF11 * AC$3:AF$3) / SUM(AC$3:AF$3)} -> 1.0388889
A12: GIGABYTE GeForce RTX 3050 Eagle OC 6G, 6GB GDDR6, 2x HDMI, 2x DP | B12: GV-N3050EAGLE OC-6GD | C12: NVIDIA | D12: =LEFT(AB12, FIND(" ", AB12 & " ") - 1) -> GIGABYTE | E12: RTX 3000 | F12: 3050 6GB | G12: 1 | H12: 6.91 | I12: 6.91 | J12: 0.11 | K12: 1750 | L12: 1750 | M12: 33.34 | N12: 75.02 | O12: 20 | P12: GDDR6 | Q12: 6 | R12: 96 | S12: 14 | T12: 70 | U12: - | V12: 4 | W12: 16 | X12: 8 | Y12: 290.5 | Z12: 295.32 | AA12: https://geizhals.eu/gigabyte-geforce-rtx-3050-eagle-oc-6g-gv-n3050eagle-oc-6gd-a3117109.html?hloc=at&hloc=de&hloc=eu&hloc=pl&hloc=uk | AB12: GIGABYTE GeForce RTX 3050 Eagle OC 6G, 6GB GDDR6, 2x HDMI, 2x DP | AC12: {=(SUMPRODUCT((H12:O12/H$9:O$9)^H$7:O$7*H$2:O$2)+SUMPRODUCT((Q12:T12/Q$9:T$9)^Q$7:T$7*Q$2:T$2))*(0.8^(1-G12))*AC$9} -> 1.0989182 | AD12: {=(SUMPRODUCT((H12:O12/H$9:O$9)^H$7:O$7*H$3:O$3)+SUMPRODUCT((Q12:T12/Q$9:T$9)^Q$7:T$7*Q$3:T$3))*(0.1^(1-G12))*AD$9} -> 1.0395387 | AE12: {=(SUMPRODUCT((H12:O12/H$9:O$9)^H$7:O$7*H$4:O$4)+SUMPRODUCT((Q12:T12/Q$9:T$9)^Q$7:T$7*Q$4:T$4))*AE$9} -> 0.94675455 | AF12: {=(SUMPRODUCT((H12:O12/H$9:O$9)^H$7:O$7*H$5:O$5)+SUMPRODUCT((Q12:T12/Q$9:T$9)^Q$7:T$7*Q$5:T$5))*AF$9} -> 0.9946504 | AG12: {=SUMPRODUCT(AC12:AF12 * AC$3:AF$3) / SUM(AC$3:AF$3)} -> 1.0316446
A13: GIGABYTE GeForce RTX 3050 OC Low Profile 6G, 6GB GDDR6, 2x HDMI, 2x DP | B13: GV-N3050OC-6GL | C13: NVIDIA | D13: =LEFT(AB13, FIND(" ", AB13 & " ") - 1) -> GIGABYTE | E13: RTX 3000 | F13: 3050 6GB | G13: 1 | H13: 6.81 | I13: 6.81 | J13: 0.11 | K13: 1750 | L13: 1750 | M13: 33.34 | N13: 75.02 | O13: 20 | P13: GDDR6 | Q13: 6 | R13: 96 | S13: 14 | T13: 70 | U13: - | V13: 4 | W13: 16 | X13: 8 | Y13: 202.34 | Z13: 269 | AA13: https://geizhals.eu/gigabyte-geforce-rtx-3050-oc-low-profile-6g-gv-n3050oc-6gl-a3117124.html?hloc=at&hloc=de&hloc=eu&hloc=pl&hloc=uk | AB13: GIGABYTE GeForce RTX 3050 OC Low Profile 6G, 6GB GDDR6, 2x HDMI, 2x DP | AC13: {=(SUMPRODUCT((H13:O13/H$9:O$9)^H$7:O$7*H$2:O$2)+SUMPRODUCT((Q13:T13/Q$9:T$9)^Q$7:T$7*Q$2:T$2))*(0.8^(1-G13))*AC$9} -> 1.0982806 | AD13: {=(SUMPRODUCT((H13:O13/H$9:O$9)^H$7:O$7*H$3:O$3)+SUMPRODUCT((Q13:T13/Q$9:T$9)^Q$7:T$7*Q$3:T$3))*(0.1^(1-G13))*AD$9} -> 1.0333695 | AE13: {=(SUMPRODUCT((H13:O13/H$9:O$9)^H$7:O$7*H$4:O$4)+SUMPRODUCT((Q13:T13/Q$9:T$9)^Q$7:T$7*Q$4:T$4))*AE$9} -> 0.94484174 | AF13: {=(SUMPRODUCT((H13:O13/H$9:O$9)^H$7:O$7*H$5:O$5)+SUMPRODUCT((Q13:T13/Q$9:T$9)^Q$7:T$7*Q$5:T$5))*AF$9} -> 0.99149685 | AG13: {=SUMPRODUCT(AC13:AF13 * AC$3:AF$3) / SUM(AC$3:AF$3)} -> 1.0273728
A14: GIGABYTE GeForce RTX 3050 Windforce OC 6G V2, 6GB GDDR6, 2x HDMI, 2x DP | B14: GV-N3050WF2OCV2-6GD | C14: NVIDIA | D14: =LEFT(AB14, FIND(" ", AB14 & " ") - 1) -> GIGABYTE | E14: RTX 3000 | F14: 3050 6GB | G14: 1 | H14: 6.81 | I14: 6.81 | J14: 0.11 | K14: 1750 | L14: 1750 | M14: 33.34 | N14: 75.02 | O14: 20 | P14: GDDR6 | Q14: 6 | R14: 96 | S14: 14 | T14: 70 | U14: - | V14: 4 | W14: 16 | X14: 8 | Y14: 194.98 | Z14: 224.95 | AA14: https://geizhals.eu/gigabyte-geforce-rtx-3050-windforce-oc-6g-v2-gv-n3050wf2ocv2-6gd-a3369266.html?hloc=at&hloc=de&hloc=eu&hloc=pl&hloc=uk | AB14: GIGABYTE GeForce RTX 3050 Windforce OC 6G V2, 6GB GDDR6, 2x HDMI, 2x DP | AC14: {=(SUMPRODUCT((H14:O14/H$9:O$9)^H$7:O$7*H$2:O$2)+SUMPRODUCT((Q14:T14/Q$9:T$9)^Q$7:T$7*Q$2:T$2))*(0.8^(1-G14))*AC$9} -> 1.0982806 | AD14: {=(SUMPRODUCT((H14:O14/H$9:O$9)^H$7:O$7*H$3:O$3)+SUMPRODUCT((Q14:T14/Q$9:T$9)^Q$7:T$7*Q$3:T$3))*(0.1^(1-G14))*AD$9} -> 1.0333695 | AE14: {=(SUMPRODUCT((H14:O14/H$9:O$9)^H$7:O$7*H$4:O$4)+SUMPRODUCT((Q14:T14/Q$9:T$9)^Q$7:T$7*Q$4:T$4))*AE$9} -> 0.94484174 | AF14: {=(SUMPRODUCT((H14:O14/H$9:O$9)^H$7:O$7*H$5:O$5)+SUMPRODUCT((Q14:T14/Q$9:T$9)^Q$7:T$7*Q$5:T$5))*AF$9} -> 0.99149685 | AG14: {=SUMPRODUCT(AC14:AF14 * AC$3:AF$3) / SUM(AC$3:AF$3)} -> 1.0273728
A15: GIGABYTE GeForce RTX 3050 Windforce OC 6G, 6GB GDDR6, 2x HDMI, 2x DP | B15: GV-N3050WF2OC-6GD | C15: NVIDIA | D15: =LEFT(AB15, FIND(" ", AB15 & " ") - 1) -> GIGABYTE | E15: RTX 3000 | F15: 3050 6GB | G15: 1 | H15: 6.81 | I15: 6.81 | J15: 0.11 | K15: 1750 | L15: 1750 | M15: 33.34 | N15: 75.02 | O15: 20 | P15: GDDR6 | Q15: 6 | R15: 96 | S15: 14 | T15: 70 | U15: - | V15: 4 | W15: 16 | X15: 8 | Y15: 197.9 | Z15: 254.43 | AA15: https://geizhals.eu/gigabyte-geforce-rtx-3050-windforce-oc-6g-gv-n3050wf2oc-6gd-a3207234.html?hloc=at&hloc=de&hloc=eu&hloc=pl&hloc=uk | AB15: GIGABYTE GeForce RTX 3050 Windforce OC 6G, 6GB GDDR6, 2x HDMI, 2x DP | AC15: {=(SUMPRODUCT((H15:O15/H$9:O$9)^H$7:O$7*H$2:O$2)+SUMPRODUCT((Q15:T15/Q$9:T$9)^Q$7:T$7*Q$2:T$2))*(0.8^(1-G15))*AC$9} -> 1.0982806 | AD15: {=(SUMPRODUCT((H15:O15/H$9:O$9)^H$7:O$7*H$3:O$3)+SUMPRODUCT((Q15:T15/Q$9:T$9)^Q$7:T$7*Q$3:T$3))*(0.1^(1-G15))*AD$9} -> 1.0333695 | AE15: {=(SUMPRODUCT((H15:O15/H$9:O$9)^H$7:O$7*H$4:O$4)+SUMPRODUCT((Q15:T15/Q$9:T$9)^Q$7:T$7*Q$4:T$4))*AE$9} -> 0.94484174 | AF15: {=(SUMPRODUCT((H15:O15/H$9:O$9)^H$7:O$7*H$5:O$5)+SUMPRODUCT((Q15:T15/Q$9:T$9)^Q$7:T$7*Q$5:T$5))*AF$9} -> 0.99149685 | AG15: {=SUMPRODUCT(AC15:AF15 * AC$3:AF$3) / SUM(AC$3:AF$3)} -> 1.0273728
A16: INNO3D GeForce RTX 3050 Twin X2, 6GB GDDR6, DVI, HDMI, DP | B16: N30502-06D6-1711VA60 | C16: NVIDIA | D16: =LEFT(AB16, FIND(" ", AB16 & " ") - 1) -> INNO3D | E16: RTX 3000 | F16: 3050 6GB | G16: 1 | H16: 6.77 | I16: 6.77 | J16: 0.11 | K16: 1750 | L16: 1750 | M16: 33.34 | N16: 75.02 | O16: 20 | P16: GDDR6 | Q16: 6 | R16: 96 | S16: 14 | T16: 70 | U16: - | V16: 4 | W16: 16 | X16: 8 | Y16: 184.95 | Z16: 267.62 | AA16: https://geizhals.eu/inno3d-geforce-rtx-3050-twin-x2-n30502-06d6-1711va60-a3170221.html?hloc=at&hloc=de&hloc=eu&hloc=pl&hloc=uk | AB16: INNO3D GeForce RTX 3050 Twin X2, 6GB GDDR6, DVI, HDMI, DP | AC16: {=(SUMPRODUCT((H16:O16/H$9:O$9)^H$7:O$7*H$2:O$2)+SUMPRODUCT((Q16:T16/Q$9:T$9)^Q$7:T$7*Q$2:T$2))*(0.8^(1-G16))*AC$9} -> 1.0980253 | AD16: {=(SUMPRODUCT((H16:O16/H$9:O$9)^H$7:O$7*H$3:O$3)+SUMPRODUCT((Q16:T16/Q$9:T$9)^Q$7:T$7*Q$3:T$3))*(0.1^(1-G16))*AD$9} -> 1.0308986 | AE16: {=(SUMPRODUCT((H16:O16/H$9:O$9)^H$7:O$7*H$4:O$4)+SUMPRODUCT((Q16:T16/Q$9:T$9)^Q$7:T$7*Q$4:T$4))*AE$9} -> 0.94407583 | AF16: {=(SUMPRODUCT((H16:O16/H$9:O$9)^H$7:O$7*H$5:O$5)+SUMPRODUCT((Q16:T16/Q$9:T$9)^Q$7:T$7*Q$5:T$5))*AF$9} -> 0.99023401 | AG16: {=SUMPRODUCT(AC16:AF16 * AC$3:AF$3) / SUM(AC$3:AF$3)} -> 1.0256619
A17: MSI GeForce RTX 3050 LP 6G OC, 6GB GDDR6, 2x HDMI, DP | B17: V812-023R | C17: NVIDIA | D17: =LEFT(AB17, FIND(" ", AB17 & " ") - 1) -> MSI | E17: RTX 3000 | F17: 3050 6GB | G17: 1 | H17: 6.88 | I17: 6.88 | J17: 0.11 | K17: 1750 | L17: 1750 | M17: 33.34 | N17: 75.02 | O17: 20 | P17: GDDR6 | Q17: 6 | R17: 96 | S17: 14 | T17: 70 | U17: - | V17: 4 | W17: 16 | X17: 8 | Y17: 195.89 | Z17: 1206.3 | AA17: https://geizhals.eu/msi-geforce-rtx-3050-lp-6g-oc-v812-023r-a3112269.html?hloc=at&hloc=de&hloc=eu&hloc=pl&hloc=uk | AB17: MSI GeForce RTX 3050 LP 6G OC, 6GB GDDR6, 2x HDMI, DP | AC17: {=(SUMPRODUCT((H17:O17/H$9:O$9)^H$7:O$7*H$2:O$2)+SUMPRODUCT((Q17:T17/Q$9:T$9)^Q$7:T$7*Q$2:T$2))*(0.8^(1-G17))*AC$9} -> 1.098727 | AD17: {=(SUMPRODUCT((H17:O17/H$9:O$9)^H$7:O$7*H$3:O$3)+SUMPRODUCT((Q17:T17/Q$9:T$9)^Q$7:T$7*Q$3:T$3))*(0.1^(1-G17))*AD$9} -> 1.0376892 | AE17: {=(SUMPRODUCT((H17:O17/H$9:O$9)^H$7:O$7*H$4:O$4)+SUMPRODUCT((Q17:T17/Q$9:T$9)^Q$7:T$7*Q$4:T$4))*AE$9} -> 0.946181 | AF17: {=(SUMPRODUCT((H17:O17/H$9:O$9)^H$7:O$7*H$5:O$5)+SUMPRODUCT((Q17:T17/Q$9:T$9)^Q$7:T$7*Q$5:T$5))*AF$9} -> 0.99370486 | AG17: {=SUMPRODUCT(AC17:AF17 * AC$3:AF$3) / SUM(AC$3:AF$3)} -> 1.0303639
A18: MSI GeForce RTX 3050 Ventus 2X 6G OC, 6GB GDDR6, 2x HDMI, DP | B18: V812-015R | C18: NVIDIA | D18: =LEFT(AB18, FIND(" ", AB18 & " ") - 1) -> MSI | E18: RTX 3000 | F18: 3050 6GB | G18: 1 | H18: 6.88 | I18: 6.88 | J18: 0.11 | K18: 1750 | L18: 1750 | M18: 33.34 | N18: 75.02 | O18: 20 | P18: GDDR6 | Q18: 6 | R18: 96 | S18: 14 | T18: 70 | U18: - | V18: 4 | W18: 16 | X18: 8 | Y18: 192.68 | Z18: 273.26 | AA18: https://geizhals.eu/msi-geforce-rtx-3050-ventus-2x-6g-oc-v812-015r-a3112267.html?hloc=at&hloc=de&hloc=eu&hloc=pl&hloc=uk | AB18: MSI GeForce RTX 3050 Ventus 2X 6G OC, 6GB GDDR6, 2x HDMI, DP | AC18: {=(SUMPRODUCT((H18:O18/H$9:O$9)^H$7:O$7*H$2:O$2)+SUMPRODUCT((Q18:T18/Q$9:T$9)^Q$7:T$7*Q$2:T$2))*(0.8^(1-G18))*AC$9} -> 1.098727 | AD18: {=(SUMPRODUCT((H18:O18/H$9:O$9)^H$7:O$7*H$3:O$3)+SUMPRODUCT((Q18:T18/Q$9:T$9)^Q$7:T$7*Q$3:T$3))*(0.1^(1-G18))*AD$9} -> 1.0376892 | AE18: {=(SUMPRODUCT((H18:O18/H$9:O$9)^H$7:O$7*H$4:O$4)+SUMPRODUCT((Q18:T18/Q$9:T$9)^Q$7:T$7*Q$4:T$4))*AE$9} -> 0.946181 | AF18: {=(SUMPRODUCT((H18:O18/H$9:O$9)^H$7:O$7*H$5:O$5)+SUMPRODUCT((Q18:T18/Q$9:T$9)^Q$7:T$7*Q$5:T$5))*AF$9} -> 0.99370486 | AG18: {=SUMPRODUCT(AC18:AF18 * AC$3:AF$3) / SUM(AC$3:AF$3)} -> 1.0303639
A19: MSI GeForce RTX 3050 Ventus 2X E 6G OC, 6GB GDDR6, 2x HDMI, DP | B19: V812-055R | C19: NVIDIA | D19: =LEFT(AB19, FIND(" ", AB19 & " ") - 1) -> MSI | E19: RTX 3000 | F19: 3050 6GB | G19: 1 | H19: 6.88 | I19: 6.88 | J19: 0.11 | K19: 1750 | L19: 1750 | M19: 33.34 | N19: 75.02 | O19: 20 | P19: GDDR6 | Q19: 6 | R19: 96 | S19: 14 | T19: 70 | U19: - | V19: 4 | W19: 16 | X19: 8 | Y19: 195.44 | Z19: 292.6 | AA19: https://geizhals.eu/msi-geforce-rtx-3050-ventus-2x-e-6g-oc-v812-055r-a3344698.html?hloc=at&hloc=de&hloc=eu&hloc=pl&hloc=uk | AB19: MSI GeForce RTX 3050 Ventus 2X E 6G OC, 6GB GDDR6, 2x HDMI, DP | AC19: {=(SUMPRODUCT((H19:O19/H$9:O$9)^H$7:O$7*H$2:O$2)+SUMPRODUCT((Q19:T19/Q$9:T$9)^Q$7:T$7*Q$2:T$2))*(0.8^(1-G19))*AC$9} -> 1.098727 | AD19: {=(SUMPRODUCT((H19:O19/H$9:O$9)^H$7:O$7*H$3:O$3)+SUMPRODUCT((Q19:T19/Q$9:T$9)^Q$7:T$7*Q$3:T$3))*(0.1^(1-G19))*AD$9} -> 1.0376892 | AE19: {=(SUMPRODUCT((H19:O19/H$9:O$9)^H$7:O$7*H$4:O$4)+SUMPRODUCT((Q19:T19/Q$9:T$9)^Q$7:T$7*Q$4:T$4))*AE$9} -> 0.946181 | AF19: {=(SUMPRODUCT((H19:O19/H$9:O$9)^H$7:O$7*H$5:O$5)+SUMPRODUCT((Q19:T19/Q$9:T$9)^Q$7:T$7*Q$5:T$5))*AF$9} -> 0.99370486 | AG19: {=SUMPRODUCT(AC19:AF19 * AC$3:AF$3) / SUM(AC$3:AF$3)} -> 1.0303639
A20: Palit GeForce RTX 3050 KalmX, 6GB GDDR6, DVI, HDMI, DP | B20: NE63050018JE-1070H | C20: NVIDIA | D20: =LEFT(AB20, FIND(" ", AB20 & " ") - 1) -> Palit | E20: RTX 3000 | F20: 3050 6GB | G20: 1 | H20: 6.77 | I20: 6.77 | J20: 0.11 | K20: 1750 | L20: 1750 | M20: 33.34 | N20: 75.02 | O20: 20 | P20: GDDR6 | Q20: 6 | R20: 96 | S20: 14 | T20: 70 | U20: - | V20: 4 | W20: 16 | X20: 8 | Y20: 199.9 | Z20: 248.51 | AA20: https://geizhals.eu/palit-geforce-rtx-3050-kalmx-ne63050018je-1070h-a3115967.html?hloc=at&hloc=de&hloc=eu&hloc=pl&hloc=uk | AB20: Palit GeForce RTX 3050 KalmX, 6GB GDDR6, DVI, HDMI, DP | AC20: {=(SUMPRODUCT((H20:O20/H$9:O$9)^H$7:O$7*H$2:O$2)+SUMPRODUCT((Q20:T20/Q$9:T$9)^Q$7:T$7*Q$2:T$2))*(0.8^(1-G20))*AC$9} -> 1.0980253 | AD20: {=(SUMPRODUCT((H20:O20/H$9:O$9)^H$7:O$7*H$3:O$3)+SUMPRODUCT((Q20:T20/Q$9:T$9)^Q$7:T$7*Q$3:T$3))*(0.1^(1-G20))*AD$9} -> 1.0308986 | AE20: {=(SUMPRODUCT((H20:O20/H$9:O$9)^H$7:O$7*H$4:O$4)+SUMPRODUCT((Q20:T20/Q$9:T$9)^Q$7:T$7*Q$4:T$4))*AE$9} -> 0.94407583 | AF20: {=(SUMPRODUCT((H20:O20/H$9:O$9)^H$7:O$7*H$5:O$5)+SUMPRODUCT((Q20:T20/Q$9:T$9)^Q$7:T$7*Q$5:T$5))*AF$9} -> 0.99023401 | AG20: {=SUMPRODUCT(AC20:AF20 * AC$3:AF$3) / SUM(AC$3:AF$3)} -> 1.0256619
A21: Palit GeForce RTX 3050 StormX, 6GB GDDR6, DVI, HDMI, DP | B21: NE63050018JE-1070F | C21: NVIDIA | D21: =LEFT(AB21, FIND(" ", AB21 & " ") - 1) -> Palit | E21: RTX 3000 | F21: 3050 6GB | G21: 1 | H21: 6.77 | I21: 6.77 | J21: 0.11 | K21: 1750 | L21: 1750 | M21: 33.34 | N21: 75.02 | O21: 20 | P21: GDDR6 | Q21: 6 | R21: 96 | S21: 14 | T21: 70 | U21: - | V21: 4 | W21: 16 | X21: 8 | Y21: 192.16 | Z21: 269.85 | AA21: https://geizhals.eu/palit-geforce-rtx-3050-stormx-ne63050018je-1070f-a3115965.html?hloc=at&hloc=de&hloc=eu&hloc=pl&hloc=uk | AB21: Palit GeForce RTX 3050 StormX, 6GB GDDR6, DVI, HDMI, DP | AC21: {=(SUMPRODUCT((H21:O21/H$9:O$9)^H$7:O$7*H$2:O$2)+SUMPRODUCT((Q21:T21/Q$9:T$9)^Q$7:T$7*Q$2:T$2))*(0.8^(1-G21))*AC$9} -> 1.0980253 | AD21: {=(SUMPRODUCT((H21:O21/H$9:O$9)^H$7:O$7*H$3:O$3)+SUMPRODUCT((Q21:T21/Q$9:T$9)^Q$7:T$7*Q$3:T$3))*(0.1^(1-G21))*AD$9} -> 1.0308986 | AE21: {=(SUMPRODUCT((H21:O21/H$9:O$9)^H$7:O$7*H$4:O$4)+SUMPRODUCT((Q21:T21/Q$9:T$9)^Q$7:T$7*Q$4:T$4))*AE$9} -> 0.94407583 | AF21: {=(SUMPRODUCT((H21:O21/H$9:O$9)^H$7:O$7*H$5:O$5)+SUMPRODUCT((Q21:T21/Q$9:T$9)^Q$7:T$7*Q$5:T$5))*AF$9} -> 0.99023401 | AG21: {=SUMPRODUCT(AC21:AF21 * AC$3:AF$3) / SUM(AC$3:AF$3)} -> 1.0256619
... A276: MSI GeForce RTX 4060 Ti Gaming X Slim 16G, 16GB GDDR6, HDMI, 3x DP | B276: V517-002R | C276: NVIDIA | D276: =LEFT(AB276, FIND(" ", AB276 & " ") - 1) -> MSI | E276: RTX 4000 | F276: 4060 Ti 16GB | G276: 1 | H276: 23.37 | I276: 23.37 | J276: 0.37 | K276: 2250 | L276: 2685 | M276: 121.7 | N276: 344.8 | O276: 30 | P276: GDDR6 | Q276: 16 | R276: 128 | S276: 18 | T276: 165 | U276: 1x 8-Pin PCIe | V276: 4 | W276: 16 | X276: 8 | Y276: 608.9 | Z276: 853 | AA276: https://geizhals.eu/msi-geforce-rtx-4060-ti-gaming-x-slim-16g-v517-002r-a2987085.html?hloc=at&hloc=de&hloc=eu&hloc=pl&hloc=uk | AB276: MSI GeForce RTX 4060 Ti Gaming X Slim 16G, 16GB GDDR6, HDMI, 3x DP | AC276: {=(SUMPRODUCT((H276:O276/H$9:O$9)^H$7:O$7*H$2:O$2)+SUMPRODUCT((Q276:T276/Q$9:T$9)^Q$7:T$7*Q$2:T$2))*(0.8^(1-G276))*AC$9} -> 1.9746611 | AD276: {=(SUMPRODUCT((H276:O276/H$9:O$9)^H$7:O$7*H$3:O$3)+SUMPRODUCT((Q276:T276/Q$9:T$9)^Q$7:T$7*Q$3:T$3))*(0.1^(1-G276))*AD$9} -> 2.2779993 | AE276: {=(SUMPRODUCT((H276:O276/H$9:O$9)^H$7:O$7*H$4:O$4)+SUMPRODUCT((Q276:T276/Q$9:T$9)^Q$7:T$7*Q$4:T$4))*AE$9} -> 2.0179136 | AF276: {=(SUMPRODUCT((H276:O276/H$9:O$9)^H$7:O$7*H$5:O$5)+SUMPRODUCT((Q276:T276/Q$9:T$9)^Q$7:T$7*Q$5:T$5))*AF$9} -> 1.9357349 | AG276: {=SUMPRODUCT(AC276:AF276 * AC$3:AF$3) / SUM(AC$3:AF$3)} -> 2.1415005
A277: MSI GeForce RTX 4060 Ti Gaming X Slim White 16G, 16GB GDDR6, HDMI, 3x DP | C277: NVIDIA | D277: =LEFT(AB277, FIND(" ", AB277 & " ") - 1) -> MSI | E277: RTX 4000 | F277: 4060 Ti 16GB | G277: 1 | H277: 23.37 | I277: 23.37 | J277: 0.37 | K277: 2250 | L277: 2685 | M277: 121.7 | N277: 344.8 | O277: 30 | P277: GDDR6 | Q277: 16 | R277: 128 | S277: 18 | T277: 165 | U277: 1x 8-Pin PCIe | V277: 4 | W277: 16 | X277: 8 | Y277: 610.5 | Z277: 969.42 | AA277: https://geizhals.eu/msi-geforce-rtx-4060-ti-gaming-x-slim-white-16g-a2987087.html?hloc=at&hloc=de&hloc=eu&hloc=pl&hloc=uk | AB277: MSI GeForce RTX 4060 Ti Gaming X Slim White 16G, 16GB GDDR6, HDMI, 3x DP | AC277: {=(SUMPRODUCT((H277:O277/H$9:O$9)^H$7:O$7*H$2:O$2)+SUMPRODUCT((Q277:T277/Q$9:T$9)^Q$7:T$7*Q$2:T$2))*(0.8^(1-G277))*AC$9} -> 1.9746611 | AD277: {=(SUMPRODUCT((H277:O277/H$9:O$9)^H$7:O$7*H$3:O$3)+SUMPRODUCT((Q277:T277/Q$9:T$9)^Q$7:T$7*Q$3:T$3))*(0.1^(1-G277))*AD$9} -> 2.2779993 | AE277: {=(SUMPRODUCT((H277:O277/H$9:O$9)^H$7:O$7*H$4:O$4)+SUMPRODUCT((Q277:T277/Q$9:T$9)^Q$7:T$7*Q$4:T$4))*AE$9} -> 2.0179136 | AF277: {=(SUMPRODUCT((H277:O277/H$9:O$9)^H$7:O$7*H$5:O$5)+SUMPRODUCT((Q277:T277/Q$9:T$9)^Q$7:T$7*Q$5:T$5))*AF$9} -> 1.9357349 | AG277: {=SUMPRODUCT(AC277:AF277 * AC$3:AF$3) / SUM(AC$3:AF$3)} -> 2.1415005
A278: MSI GeForce RTX 4060 Ti Ventus 2X Black 16G OC, 16GB GDDR6, HDMI, 3x DP | B278: V517-005R | C278: NVIDIA | D278: =LEFT(AB278, FIND(" ", AB278 & " ") - 1) -> MSI | E278: RTX 4000 | F278: 4060 Ti 16GB | G278: 1 | H278: 22.85 | I278: 22.85 | J278: 0.36 | K278: 2250 | L278: 2625 | M278: 121.7 | N278: 344.8 | O278: 30 | P278: GDDR6 | Q278: 16 | R278: 128 | S278: 18 | T278: 165 | U278: 1x 8-Pin PCIe | V278: 4 | W278: 16 | X278: 8 | Y278: 579 | Z278: 981.31 | AA278: https://geizhals.eu/msi-geforce-rtx-4060-ti-ventus-2x-black-16g-oc-a2986992.html?hloc=at&hloc=de&hloc=eu&hloc=pl&hloc=uk | AB278: MSI GeForce RTX 4060 Ti Ventus 2X Black 16G OC, 16GB GDDR6, HDMI, 3x DP | AC278: {=(SUMPRODUCT((H278:O278/H$9:O$9)^H$7:O$7*H$2:O$2)+SUMPRODUCT((Q278:T278/Q$9:T$9)^Q$7:T$7*Q$2:T$2))*(0.8^(1-G278))*AC$9} -> 1.9643254 | AD278: {=(SUMPRODUCT((H278:O278/H$9:O$9)^H$7:O$7*H$3:O$3)+SUMPRODUCT((Q278:T278/Q$9:T$9)^Q$7:T$7*Q$3:T$3))*(0.1^(1-G278))*AD$9} -> 2.2462296 | AE278: {=(SUMPRODUCT((H278:O278/H$9:O$9)^H$7:O$7*H$4:O$4)+SUMPRODUCT((Q278:T278/Q$9:T$9)^Q$7:T$7*Q$4:T$4))*AE$9} -> 1.9890789 | AF278: {=(SUMPRODUCT((H278:O278/H$9:O$9)^H$7:O$7*H$5:O$5)+SUMPRODUCT((Q278:T278/Q$9:T$9)^Q$7:T$7*Q$5:T$5))*AF$9} -> 1.9184158 | AG278: {=SUMPRODUCT(AC278:AF278 * AC$3:AF$3) / SUM(AC$3:AF$3)} -> 2.1160376
A279: MSI GeForce RTX 4060 Ti Ventus 3X 16G OC, 16GB GDDR6, HDMI, 3x DP | B279: V517-004R | C279: NVIDIA | D279: =LEFT(AB279, FIND(" ", AB279 & " ") - 1) -> MSI | E279: RTX 4000 | F279: 4060 Ti 16GB | G279: 1 | H279: 22.85 | I279: 22.85 | J279: 0.36 | K279: 2250 | L279: 2625 | M279: 121.7 | N279: 344.8 | O279: 30 | P279: GDDR6 | Q279: 16 | R279: 128 | S279: 18 | T279: 165 | U279: 1x 8-Pin PCIe | V279: 4 | W279: 16 | X279: 8 | Y279: 542.9 | Z279: 1050.49 | AA279: https://geizhals.eu/msi-geforce-rtx-4060-ti-ventus-3x-16g-oc-v517-004r-a2987084.html?hloc=at&hloc=de&hloc=eu&hloc=pl&hloc=uk | AB279: MSI GeForce RTX 4060 Ti Ventus 3X 16G OC, 16GB GDDR6, HDMI, 3x DP | AC279: {=(SUMPRODUCT((H279:O279/H$9:O$9)^H$7:O$7*H$2:O$2)+SUMPRODUCT((Q279:T279/Q$9:T$9)^Q$7:T$7*Q$2:T$2))*(0.8^(1-G279))*AC$9} -> 1.9643254 | AD279: {=(SUMPRODUCT((H279:O279/H$9:O$9)^H$7:O$7*H$3:O$3)+SUMPRODUCT((Q279:T279/Q$9:T$9)^Q$7:T$7*Q$3:T$3))*(0.1^(1-G279))*AD$9} -> 2.2462296 | AE279: {=(SUMPRODUCT((H279:O279/H$9:O$9)^H$7:O$7*H$4:O$4)+SUMPRODUCT((Q279:T279/Q$9:T$9)^Q$7:T$7*Q$4:T$4))*AE$9} -> 1.9890789 | AF279: {=(SUMPRODUCT((H279:O279/H$9:O$9)^H$7:O$7*H$5:O$5)+SUMPRODUCT((Q279:T279/Q$9:T$9)^Q$7:T$7*Q$5:T$5))*AF$9} -> 1.9184158 | AG279: {=SUMPRODUCT(AC279:AF279 * AC$3:AF$3) / SUM(AC$3:AF$3)} -> 2.1160376
A280: Palit GeForce RTX 4060 Ti JetStream, 16GB GDDR6, HDMI, 3x DP | B280: NE6406T019T1-1061J | C280: NVIDIA | D280: =LEFT(AB280, FIND(" ", AB280 & " ") - 1) -> Palit | E280: RTX 4000 | F280: 4060 Ti 16GB | G280: 1 | H280: 22.06 | I280: 22.06 | J280: 0.34 | K280: 2250 | L280: 2535 | M280: 121.7 | N280: 344.8 | O280: 30 | P280: GDDR6 | Q280: 16 | R280: 128 | S280: 18 | T280: 165 | U280: 1x 8-Pin PCIe | V280: 4 | W280: 16 | X280: 8 | Y280: 567.98 | Z280: 753.99 | AA280: https://geizhals.eu/palit-geforce-rtx-4060-ti-jetstream-ne6406t019t1-1061j-a3014701.html?hloc=at&hloc=de&hloc=eu&hloc=pl&hloc=uk | AB280: Palit GeForce RTX 4060 Ti JetStream, 16GB GDDR6, HDMI, 3x DP | AC280: {=(SUMPRODUCT((H280:O280/H$9:O$9)^H$7:O$7*H$2:O$2)+SUMPRODUCT((Q280:T280/Q$9:T$9)^Q$7:T$7*Q$2:T$2))*(0.8^(1-G280))*AC$9} -> 1.9487207 | AD280: {=(SUMPRODUCT((H280:O280/H$9:O$9)^H$7:O$7*H$3:O$3)+SUMPRODUCT((Q280:T280/Q$9:T$9)^Q$7:T$7*Q$3:T$3))*(0.1^(1-G280))*AD$9} -> 2.1964078 | AE280: {=(SUMPRODUCT((H280:O280/H$9:O$9)^H$7:O$7*H$4:O$4)+SUMPRODUCT((Q280:T280/Q$9:T$9)^Q$7:T$7*Q$4:T$4))*AE$9} -> 1.9352673 | AF280: {=(SUMPRODUCT((H280:O280/H$9:O$9)^H$7:O$7*H$5:O$5)+SUMPRODUCT((Q280:T280/Q$9:T$9)^Q$7:T$7*Q$5:T$5))*AF$9} -> 1.8920797 | AG280: {=SUMPRODUCT(AC280:AF280 * AC$3:AF$3) / SUM(AC$3:AF$3)} -> 2.0753897
A281: Zotac Gaming GeForce RTX 4060 Ti Twin Edge, 16GB GDDR6, HDMI, 3x DP | B281: ZT-D40620E-10M | C281: NVIDIA | D281: =LEFT(AB281, FIND(" ", AB281 & " ") - 1) -> Zotac | E281: RTX 4000 | F281: 4060 Ti 16GB | G281: 1 | H281: 22.06 | I281: 22.06 | J281: 0.34 | K281: 2250 | L281: 2535 | M281: 121.7 | N281: 344.8 | O281: 30 | P281: GDDR6 | Q281: 16 | R281: 128 | S281: 18 | T281: 165 | U281: 1x 8-Pin PCIe | V281: 4 | W281: 16 | X281: 8 | Y281: 579.54 | Z281: 994.08 | AA281: https://geizhals.eu/zotac-gaming-geforce-rtx-4060-ti-twin-edge-zt-d40620e-10m-a2951637.html?hloc=at&hloc=de&hloc=eu&hloc=pl&hloc=uk | AB281: Zotac Gaming GeForce RTX 4060 Ti Twin Edge, 16GB GDDR6, HDMI, 3x DP | AC281: {=(SUMPRODUCT((H281:O281/H$9:O$9)^H$7:O$7*H$2:O$2)+SUMPRODUCT((Q281:T281/Q$9:T$9)^Q$7:T$7*Q$2:T$2))*(0.8^(1-G281))*AC$9} -> 1.9487207 | AD281: {=(SUMPRODUCT((H281:O281/H$9:O$9)^H$7:O$7*H$3:O$3)+SUMPRODUCT((Q281:T281/Q$9:T$9)^Q$7:T$7*Q$3:T$3))*(0.1^(1-G281))*AD$9} -> 2.1964078 | AE281: {=(SUMPRODUCT((H281:O281/H$9:O$9)^H$7:O$7*H$4:O$4)+SUMPRODUCT((Q281:T281/Q$9:T$9)^Q$7:T$7*Q$4:T$4))*AE$9} -> 1.9352673 | AF281: {=(SUMPRODUCT((H281:O281/H$9:O$9)^H$7:O$7*H$5:O$5)+SUMPRODUCT((Q281:T281/Q$9:T$9)^Q$7:T$7*Q$5:T$5))*AF$9} -> 1.8920797 | AG281: {=SUMPRODUCT(AC281:AF281 * AC$3:AF$3) / SUM(AC$3:AF$3)} -> 2.0753897
A282: Zotac GeForce RTX 4060 Ti AMP SPIDER-MAN: Across the Spider-Verse Bundle, 16GB GDDR6, HDMI, 3x DP | B282: ZT-D40620F-10SMP | C282: NVIDIA | D282: =LEFT(AB282, FIND(" ", AB282 & " ") - 1) -> Zotac | E282: RTX 4000 | F282: 4060 Ti 16GB | G282: 1 | H282: 22.59 | I282: 22.59 | J282: 0.35 | K282: 2250 | L282: 2595 | M282: 121.7 | N282: 344.8 | O282: 30 | P282: GDDR6 | Q282: 16 | R282: 128 | S282: 18 | T282: 165 | U282: 1x 8-Pin PCIe | V282: 4 | W282: 16 | X282: 8 | Y282: 927.52 | Z282: 927.52 | AA282: https://geizhals.eu/zotac-geforce-rtx-4060-ti-amp-spider-man-across-the-spider-verse-bundle-zt-d40620f-10smp-a2987822.html?hloc=at&hloc=de&hloc=eu&hloc=pl&hloc=uk | AB282: Zotac GeForce RTX 4060 Ti AMP SPIDER-MAN: Across the Spider-Verse Bundle, 16GB GDDR6, HDMI, 3x DP | AC282: {=(SUMPRODUCT((H282:O282/H$9:O$9)^H$7:O$7*H$2:O$2)+SUMPRODUCT((Q282:T282/Q$9:T$9)^Q$7:T$7*Q$2:T$2))*(0.8^(1-G282))*AC$9} -> 1.9591487 | AD282: {=(SUMPRODUCT((H282:O282/H$9:O$9)^H$7:O$7*H$3:O$3)+SUMPRODUCT((Q282:T282/Q$9:T$9)^Q$7:T$7*Q$3:T$3))*(0.1^(1-G282))*AD$9} -> 2.2288671 | AE282: {=(SUMPRODUCT((H282:O282/H$9:O$9)^H$7:O$7*H$4:O$4)+SUMPRODUCT((Q282:T282/Q$9:T$9)^Q$7:T$7*Q$4:T$4))*AE$9} -> 1.9645295 | AF282: {=(SUMPRODUCT((H282:O282/H$9:O$9)^H$7:O$7*H$5:O$5)+SUMPRODUCT((Q282:T282/Q$9:T$9)^Q$7:T$7*Q$5:T$5))*AF$9} -> 1.9097404 | AG282: {=SUMPRODUCT(AC282:AF282 * AC$3:AF$3) / SUM(AC$3:AF$3)} -> 2.1013554
A283: Zotac GeForce RTX 4060 Ti AMP, 16GB GDDR6, HDMI, 3x DP | B283: ZT-D40620F-10M | C283: NVIDIA | D283: =LEFT(AB283, FIND(" ", AB283 & " ") - 1) -> Zotac | E283: RTX 4000 | F283: 4060 Ti 16GB | G283: 1 | H283: 22.59 | I283: 22.59 | J283: 0.35 | K283: 2250 | L283: 2595 | M283: 121.7 | N283: 344.8 | O283: 30 | P283: GDDR6 | Q283: 16 | R283: 128 | S283: 18 | T283: 165 | U283: 1x 8-Pin PCIe | V283: 4 | W283: 16 | X283: 8 | Y283: 609 | Z283: 1046.53 | AA283: https://geizhals.eu/zotac-geforce-rtx-4060-ti-amp-zt-d40620f-10m-a3050859.html?hloc=at&hloc=de&hloc=eu&hloc=pl&hloc=uk | AB283: Zotac GeForce RTX 4060 Ti AMP, 16GB GDDR6, HDMI, 3x DP | AC283: {=(SUMPRODUCT((H283:O283/H$9:O$9)^H$7:O$7*H$2:O$2)+SUMPRODUCT((Q283:T283/Q$9:T$9)^Q$7:T$7*Q$2:T$2))*(0.8^(1-G283))*AC$9} -> 1.9591487 | AD283: {=(SUMPRODUCT((H283:O283/H$9:O$9)^H$7:O$7*H$3:O$3)+SUMPRODUCT((Q283:T283/Q$9:T$9)^Q$7:T$7*Q$3:T$3))*(0.1^(1-G283))*AD$9} -> 2.2288671 | AE283: {=(SUMPRODUCT((H283:O283/H$9:O$9)^H$7:O$7*H$4:O$4)+SUMPRODUCT((Q283:T283/Q$9:T$9)^Q$7:T$7*Q$4:T$4))*AE$9} -> 1.9645295 | AF283: {=(SUMPRODUCT((H283:O283/H$9:O$9)^H$7:O$7*H$5:O$5)+SUMPRODUCT((Q283:T283/Q$9:T$9)^Q$7:T$7*Q$5:T$5))*AF$9} -> 1.9097404 | AG283: {=SUMPRODUCT(AC283:AF283 * AC$3:AF$3) / SUM(AC$3:AF$3)} -> 2.1013554
A284: ASUS Dual GeForce RTX 4070 EVO OC, DUAL-RTX4070-O12GD6-EVO, 12GB GDDR6, HDMI, 3x DP | B284: 90YV0LM0-M0NA00 | C284: NVIDIA | D284: =LEFT(AB284, FIND(" ", AB284 & " ") - 1) -> ASUS | E284: RTX 4000 | F284: 4070 12GB | G284: 1 | H284: 30.03 | I284: 30.03 | J284: 0.47 | K284: 2500 | L284: 2550 | M284: 122.9 | N284: 353.3 | O284: 46 | P284: GDDR6 | Q284: 12 | R284: 192 | S284: 20 | T284: 200 | U284: 1x 8-Pin PCIe | V284: 4 | W284: 16 | X284: 16 | Y284: 629.85 | Z284: 1133.99 | AA284: https://geizhals.eu/asus-dual-geforce-rtx-4070-evo-oc-a3294387.html?hloc=at&hloc=de&hloc=eu&hloc=pl&hloc=uk | AB284: ASUS Dual GeForce RTX 4070 EVO OC, DUAL-RTX4070-O12GD6-EVO, 12GB GDDR6, HDMI, 3x DP | AC284: {=(SUMPRODUCT((H284:O284/H$9:O$9)^H$7:O$7*H$2:O$2)+SUMPRODUCT((Q284:T284/Q$9:T$9)^Q$7:T$7*Q$2:T$2))*(0.8^(1-G284))*AC$9} -> 2.09993 | AD284: {=(SUMPRODUCT((H284:O284/H$9:O$9)^H$7:O$7*H$3:O$3)+SUMPRODUCT((Q284:T284/Q$9:T$9)^Q$7:T$7*Q$3:T$3))*(0.1^(1-G284))*AD$9} -> 2.635662 | AE284: {=(SUMPRODUCT((H284:O284/H$9:O$9)^H$7:O$7*H$4:O$4)+SUMPRODUCT((Q284:T284/Q$9:T$9)^Q$7:T$7*Q$4:T$4))*AE$9} -> 2.3587132 | AF284: {=(SUMPRODUCT((H284:O284/H$9:O$9)^H$7:O$7*H$5:O$5)+SUMPRODUCT((Q284:T284/Q$9:T$9)^Q$7:T$7*Q$5:T$5))*AF$9} -> 2.2037026 | AG284: {=SUMPRODUCT(AC284:AF284 * AC$3:AF$3) / SUM(AC$3:AF$3)} -> 2.443608
A285: ASUS Dual GeForce RTX 4070 EVO OC, DUAL-RTX4070-O12G-EVO, 12GB GDDR6X, HDMI, 3x DP | B285: 90YV0J15-M0NA00 | C285: NVIDIA | D285: =LEFT(AB285, FIND(" ", AB285 & " ") - 1) -> ASUS | E285: RTX 4000 | F285: 4070 12GB | G285: 1 | H285: 30.03 | I285: 30.03 | J285: 0.47 | K285: 1313 | L285: 2550 | M285: 122.9 | N285: 353.3 | O285: 46 | P285: GDDR6X | Q285: 12 | R285: 192 | S285: 21 | T285: 200 | U285: 1x 8-Pin PCIe | V285: 4 | W285: 16 | X285: 16 | Y285: 672.8 | Z285: 1179.5 | AA285: https://geizhals.eu/asus-dual-geforce-rtx-4070-evo-oc-90yv0j15-m0na00-a3105789.html?hloc=at&hloc=de&hloc=eu&hloc=pl&hloc=uk | AB285: ASUS Dual GeForce RTX 4070 EVO OC, DUAL-RTX4070-O12G-EVO, 12GB GDDR6X, HDMI, 3x DP | AC285: {=(SUMPRODUCT((H285:O285/H$9:O$9)^H$7:O$7*H$2:O$2)+SUMPRODUCT((Q285:T285/Q$9:T$9)^Q$7:T$7*Q$2:T$2))*(0.8^(1-G285))*AC$9} -> 2.0142705 | AD285: {=(SUMPRODUCT((H285:O285/H$9:O$9)^H$7:O$7*H$3:O$3)+SUMPRODUCT((Q285:T285/Q$9:T$9)^Q$7:T$7*Q$3:T$3))*(0.1^(1-G285))*AD$9} -> 2.6079913 | AE285: {=(SUMPRODUCT((H285:O285/H$9:O$9)^H$7:O$7*H$4:O$4)+SUMPRODUCT((Q285:T285/Q$9:T$9)^Q$7:T$7*Q$4:T$4))*AE$9} -> 2.3336898 | AF285: {=(SUMPRODUCT((H285:O285/H$9:O$9)^H$7:O$7*H$5:O$5)+SUMPRODUCT((Q285:T285/Q$9:T$9)^Q$7:T$7*Q$5:T$5))*AF$9} -> 2.1483612 | AG285: {=SUMPRODUCT(AC285:AF285 * AC$3:AF$3) / SUM(AC$3:AF$3)} -> 2.4019549
